Workbook

Sheet CONSOLIDADO 
A2: B/T MOQUEGUA - B/T TABLONES - B/T HUEMUL - B/T CONCON TRADER MARGEN DE OPERACIÓN CONSOLIDADO - PROYECTADO A JULIO 2026
A4: B/T Moquegua / B/T Tablones / B/T Huemul / B/T Concon Trader | B4: ENERO | C4: FEBRERO | D4: MARZO | E4: ABRIL | F4: MAYO | G4: JUNIO (*) | H4: JULIO (**) | I4: AGOSTO | J4: SETIEMBRE | K4: OCTUBRE | L4: NOVIEMBRE | M4: DICIEMBRE | N4: TOTAL
A6: Facturación flete | B6: =+SUM('BT MOQUEGUA MEC '!B5:B6)+'BT TABLONES JN'!B5 -> 1041229.8 | C6: =+SUM('BT MOQUEGUA MEC '!C5:C6)+'BT TABLONES JN'!C5 -> 1827319 | D6: =+SUM('BT MOQUEGUA MEC '!D5:D6)+'BT TABLONES JN'!D5 -> 1992698 | E6: =+SUM('BT MOQUEGUA MEC '!E5:E6)+'BT TABLONES JN'!E5 -> 1361977.2 | F6: =+SUM('BT MOQUEGUA MEC '!F5:F6)+'BT TABLONES JN'!F5+'BT HUEMUL-CONCON TRADER'!F5 -> 2170960 | G6: =+SUM('BT MOQUEGUA MEC '!G5:G6)+'BT TABLONES JN'!G5+'BT HUEMUL-CONCON TRADER'!G5 -> 2439971.5 | H6: =+SUM('BT MOQUEGUA MEC '!H5:H6)+'BT TABLONES JN'!H5 -> 1826435 | I6: =+SUM('BT MOQUEGUA MEC '!I5:I6)+'BT TABLONES JN'!I5 -> 0 | J6: =+SUM('BT MOQUEGUA MEC '!J5:J6)+'BT TABLONES JN'!J5 -> 0 | K6: =+SUM('BT MOQUEGUA MEC '!K5:K6)+'BT TABLONES JN'!K5 -> 0 | L6: =+SUM('BT MOQUEGUA MEC '!L5:L6)+'BT TABLONES JN'!L5 -> 0 | M6: =+SUM('BT MOQUEGUA MEC '!M5:M6)+'BT TABLONES JN'!M5 -> 0 | N6: =SUM(B6:M6) -> 12660590
A7: Facturación ingresos de puerto | B7: =+SUM('BT MOQUEGUA MEC '!B7:B9)+'BT TABLONES JN'!B6+'BT TABLONES JN'!B7 -> 76148 | C7: =+SUM('BT MOQUEGUA MEC '!C7:C9)+'BT TABLONES JN'!C6+'BT TABLONES JN'!C7 -> 68523 | D7: =+SUM('BT MOQUEGUA MEC '!D7:D9)+'BT TABLONES JN'!D6+'BT TABLONES JN'!D7 -> 103740 | E7: =+SUM('BT MOQUEGUA MEC '!E7:E9)+'BT TABLONES JN'!E6+'BT TABLONES JN'!E7 -> 76378 | F7: =+SUM('BT MOQUEGUA MEC '!F7:F9)+'BT TABLONES JN'!F6+'BT TABLONES JN'!F7 -> 66224 | G7: =+SUM('BT MOQUEGUA MEC '!G7:G9)+'BT TABLONES JN'!G6+'BT TABLONES JN'!G7 -> 104100 | H7: =+SUM('BT MOQUEGUA MEC '!H7:H9)+'BT TABLONES JN'!H6+'BT TABLONES JN'!H7 -> 82000 | I7: =+SUM('BT MOQUEGUA MEC '!I7:I9)+'BT TABLONES JN'!I6+'BT TABLONES JN'!I7 -> 0 | ... M7: =+SUM('BT MOQUEGUA MEC '!M7:M9)+'BT TABLONES JN'!M6+'BT TABLONES JN'!M7 -> 0 | N7: =SUM(B7:M7) -> 577113
A8: Demoras | B8: =+'BT MOQUEGUA MEC '!B10+'BT MOQUEGUA MEC '!B11+'BT TABLONES JN'!B8 -> 604689 | C8: =+SUM('BT MOQUEGUA MEC '!C10:C11)+'BT TABLONES JN'!C8 -> 215350 | D8: =+SUM('BT MOQUEGUA MEC '!D10:D11)+'BT TABLONES JN'!D8 -> 562537 | E8: =+SUM('BT MOQUEGUA MEC '!E10:E11)+'BT TABLONES JN'!E8 -> 484965 | F8: =+SUM('BT MOQUEGUA MEC '!F10:F11)+'BT TABLONES JN'!F8+'BT HUEMUL-CONCON TRADER'!F8 -> 465646 | G8: =+SUM('BT MOQUEGUA MEC '!G10:G11)+'BT TABLONES JN'!G8 -> 185299.48 | H8: =+SUM('BT MOQUEGUA MEC '!H10:H11)+'BT TABLONES JN'!H8 -> 100000 | I8: =+SUM('BT MOQUEGUA MEC '!I10:I11)+'BT TABLONES JN'!I8 -> 0 | J8: =+SUM('BT MOQUEGUA MEC '!J10:J11)+'BT TABLONES JN'!J8 -> 0 | K8: =+SUM('BT MOQUEGUA MEC '!K10:K11)+'BT TABLONES JN'!K8 -> 0 | L8: =+SUM('BT MOQUEGUA MEC '!L10:L11)+'BT TABLONES JN'!L8 -> 0 | M8: =+SUM('BT MOQUEGUA MEC '!M10:M11)+'BT TABLONES JN'!M8 -> 0 | N8: =SUM(B8:M8) -> 2618486.5
A9: Facturacion otros | B9: =+'BT TABLONES JN'!B9 -> 0 | C9: =+'BT TABLONES JN'!C9 -> 0 | D9: =+'BT TABLONES JN'!D9 -> 0 | E9: =+'BT TABLONES JN'!E9 -> 0 | F9: =+'BT TABLONES JN'!F9 -> 0 | G9: =+'BT TABLONES JN'!G9 -> 0 | H9: =+'BT TABLONES JN'!H9 -> 0 | I9: =+'BT TABLONES JN'!I9 -> 0 | ... M9: =+'BT TABLONES JN'!M9 -> 0 | N9: =SUM(B9:M9) -> 0
A10: Otros ingresos | B10: =+'BT TABLONES JN'!B11 -> 0 | C10: =+'BT TABLONES JN'!C11 -> 0 | D10: =+'BT TABLONES JN'!D11 -> 0 | E10: =+'BT TABLONES JN'!E11 -> 0 | F10: =+'BT TABLONES JN'!F11 -> 0 | G10: =+'BT TABLONES JN'!G11 -> 0 | H10: =+'BT TABLONES JN'!H11 -> 0 | I10: =+'BT TABLONES JN'!I11 -> 0 | ... M10: =+'BT TABLONES JN'!M11 -> 0 | N10: =SUM(B10:M10) -> 0
A11: Total Ingresos | B11: =SUM(B6:B10) -> 1722066.8 | C11: =SUM(C6:C10) -> 2111192 | D11: =SUM(D6:D10) -> 2658975 | E11: =SUM(E6:E10) -> 1923320.2 | F11: =SUM(F6:F10) -> 2702830 | G11: =SUM(G6:G10) -> 2729371 | H11: =SUM(H6:H10) -> 2008435 | I11: =SUM(I6:I10) -> 0 | ... M11: =SUM(M6:M10) -> 0 | N11: =SUM(B11:M11) -> 15856190
A13: Bunker Moquegua y Tablones | B13: =-(+'BT MOQUEGUA MEC '!B13+'BT TABLONES JN'!B16) -> -177692 | C13: =-(+'BT MOQUEGUA MEC '!C13+'BT TABLONES JN'!C16) -> -232202 | D13: =-(+'BT MOQUEGUA MEC '!D13+'BT TABLONES JN'!D16) -> -187359 | E13: =-(+'BT MOQUEGUA MEC '!E13+'BT TABLONES JN'!E16) -> -189899 | F13: =-(+'BT MOQUEGUA MEC '!F13+'BT TABLONES JN'!F16) -> -237922 | G13: =-(+'BT MOQUEGUA MEC '!G13+'BT TABLONES JN'!G16) -> -300000 | H13: =-(+'BT MOQUEGUA MEC '!H13+'BT TABLONES JN'!H16) -> -310000 | I13: =-(+'BT MOQUEGUA MEC '!I13+'BT TABLONES JN'!I16) -> 0 | ... M13: =-(+'BT MOQUEGUA MEC '!M13+'BT TABLONES JN'!M16) -> 0 | N13: =SUM(B13:M13) -> -1635074
A14: Costos portuarios | B14: =-(+'BT MOQUEGUA MEC '!B14+'BT TABLONES JN'!B17) -> -315780 | C14: =-(+'BT MOQUEGUA MEC '!C14+'BT TABLONES JN'!C17) -> -483482 | D14: =-(+'BT MOQUEGUA MEC '!D14+'BT TABLONES JN'!D17) -> -393685 | E14: =-(+SUM('BT MOQUEGUA MEC '!E14)+'BT TABLONES JN'!E17) -> -259361 | F14: =-(+SUM('BT MOQUEGUA MEC '!F14)+'BT TABLONES JN'!F17) -> -330840 | G14: =-(+SUM('BT MOQUEGUA MEC '!G14)+'BT TABLONES JN'!G17) -> -450000 | H14: =-(+SUM('BT MOQUEGUA MEC '!H14)+'BT TABLONES JN'!H17) -> -448000 | I14: =-(+SUM('BT MOQUEGUA MEC '!I14)+'BT TABLONES JN'!I17) -> 0 | J14: =-(+SUM('BT MOQUEGUA MEC '!J14)+'BT TABLONES JN'!J17) -> 0 | K14: =-(+SUM('BT MOQUEGUA MEC '!K14)+'BT TABLONES JN'!K17) -> 0 | L14: =-(+SUM('BT MOQUEGUA MEC '!L14)+'BT TABLONES JN'!L17) -> 0 | M14: =-(+SUM('BT MOQUEGUA MEC '!M14)+'BT TABLONES JN'!M17) -> 0 | N14: =SUM(B14:M14) -> -2681148
A15: Comisiones Varias / otros costos | B15: =-(+'BT MOQUEGUA MEC '!B15) -> 0 | C15: =-(+'BT MOQUEGUA MEC '!C15) -> 0 | D15: =-(+'BT MOQUEGUA MEC '!D15) -> 0 | E15: =-(+'BT MOQUEGUA MEC '!E15) -> 0 | F15: =-'BT TABLONES JN'!F19 -> -1015 | G15: =-(+'BT MOQUEGUA MEC '!G15) -> 0 | H15: =-(+'BT MOQUEGUA MEC '!H15) -> 0 | I15: =-(+'BT MOQUEGUA MEC '!I15) -> 0 | J15: =-(+'BT MOQUEGUA MEC '!J15) -> 0 | K15: =-(+'BT MOQUEGUA MEC '!K15) -> 0 | L15: =-(+'BT MOQUEGUA MEC '!L15) -> 0 | M15: =-(+'BT MOQUEGUA MEC '!M15) -> 0 | N15: =SUM(B15:M15) -> -1015
A16: Demora a Huemul V.105 | C16: =+'BT TABLONES JN'!C19 -> 0 | F16: =-'BT HUEMUL-CONCON TRADER'!F17 -> -112500 | N16: =SUM(B16:M16) -> -112500
A17: Costo arriendo otras naves - Huemul V.105 | B17: =-(+'BT TABLONES JN'!B24) -> 0 | C17: =-(+'BT TABLONES JN'!C24) -> 0 | D17: =-(+'BT TABLONES JN'!D24) -> 0 | E17: =-(+'BT TABLONES JN'!E24) -> 0 | F17: =-'BT HUEMUL-CONCON TRADER'!F18 -> -417912 | G17: =-'BT HUEMUL-CONCON TRADER'!G18 -> -359800 | H17: =-(+'BT TABLONES JN'!H24) -> 0 | I17: =-(+'BT TABLONES JN'!I24) -> 0 | J17: =-(+'BT TABLONES JN'!J24) -> 0 | K17: =-(+'BT TABLONES JN'!K24) -> 0 | L17: =-(+'BT TABLONES JN'!L24) -> 0 | M17: =-(+'BT TABLONES JN'!M24) -> 0 | N17: =SUM(B17:M17) -> -777712
A18: Total Egresos | B18: =+SUM(B13:B17) -> -493472 | C18: =+SUM(C13:C17) -> -715684 | D18: =+SUM(D13:D17) -> -581044 | E18: =+SUM(E13:E17) -> -449260 | F18: =+SUM(F13:F17) -> -1100189 | G18: =+SUM(G13:G17) -> -1109800 | H18: =+SUM(H13:H17) -> -758000 | I18: =+SUM(I13:I17) -> 0 | ... M18: =+SUM(M13:M17) -> 0 | N18: =SUM(B18:M18) -> -5207449
A20: Margen de Operación | B20: =+B11+B18 -> 1228594.8 | C20: =+C11+C18 -> 1395508 | D20: =+D11+D18 -> 2077931 | E20: =+E11+E18 -> 1474060.2 | F20: =+F11+F18 -> 1602641 | G20: =+G11+G18 -> 1619571 | H20: =+H11+H18 -> 1250435 | I20: =+I11+I18 -> 0 | ... M20: =+M11+M18 -> 0 | N20: =SUM(B20:M20) -> 10648741
A22: Fecha: 11.06.2026
A23: Tasa de demora: USD 20,000
A25: (*) Proyección a Junio:
A26: Tablones: Cuatro viajes de exportación
A27: Moquegua: Un viaje de exportación y dos viajes de cabotaje (uno es NEXA)
A29: (**) Proyección a Julio:
A30: Tablones: Dos viajes de exportación y un viaje de cabotaje
A31: Moquegua: Tres viajes de exportación y un viaje de cabotaje
A33: En base a la provisión por demoras y gastos portuarios de Sandra Galvez.
A34: En el mes de enero se consideró el pago por light dues 2026

Sheet BT MOQUEGUA MEC 
A2: B/T MOQUEGUA - MARGEN DE OPERACIÓN - PROYECTADO A JULIO 2026
A4: CONCEPTO | B4: ENERO | C4: FEBRERO | D4: MARZO | E4: ABRIL | F4: MAYO | G4: JUNIO (*) | H4: JULIO (**) | I4: AGOSTO | J4: SETIEMBRE | K4: OCTUBRE | L4: NOVIEMBRE | M4: DICIEMBRE | N4: TOTAL
A5: Facturación flete Moquegua | B5: 197160 | C5: 1018422 | D5: 1132813 | E5: 547916 | F5: 1220212 | G5: 972970 | H5: 1013180 | N5: =SUM(B5:M5) -> 6102673
A6: Facturación aceite vegetal | N6: =SUM(B6:M6) -> 0
A7: Reintegro Muellaje / Recalada muelle adicional / Full speeed | B7: 22301 | C7: 6766 | D7: 77437 | E7: 21218 | F7: 32657 | G7: 24100 | H7: 42000 | N7: =SUM(B7:M7) -> 226479
A8: Facturación reintegro Marcona | N8: =SUM(B8:M8) -> 0
A9: Facturación por segundo ingreso puerto/cambio de muelle | N9: =SUM(B9:M9) -> 0
A10: Demora ácido sulfúrico | B10: 331565 | C10: 130225 | D10: 226211 | E10: 296524 | F10: 61681 | G10: 111000 | H10: 50000 | N10: =SUM(B10:M10) -> 1207206
A11: Demora aceite vegetal | N11: =SUM(B11:M11) -> 0
A12: Total Ingresos | B12: =SUM(B5:B11) -> 551026 | C12: =SUM(C5:C10) -> 1155413 | D12: =SUM(D5:D11) -> 1436461 | E12: =SUM(E5:E11) -> 865658 | F12: =SUM(F5:F11) -> 1314550 | G12: =SUM(G5:G11) -> 1108070 | H12: =SUM(H5:H11) -> 1105180 | I12: =SUM(I5:I11) -> 0 | J12: =SUM(J5:J11) -> 0 | K12: =SUM(K5:K11) -> 0 | ... M12: =SUM(M5:M11) -> 0 | N12: =SUM(B12:M12) -> 7536358
A13: Bunker | B13: 58114 | C13: 104267 | D13: 109571 | E13: 82632 | F13: 99174 | G13: 120000 | H13: 145000 | N13: =SUM(B13:M13) -> 718758 | W13: =SUM(S13:V13) -> 0
A14: Costos portuarios Moquegua | B14: 55351 | C14: 166092 | D14: 337777 | E14: 62342 | F14: 219414 | G14: 158000 | H14: 243000 | N14: =SUM(B14:M14) -> 1241976
A15: Comisiones varias / Otros costos directos | N15: =SUM(B15:M15) -> 0
A16: Total Egresos | B16: =SUM(B13:B15) -> 113465 | C16: =SUM(C13:C15) -> 270359 | D16: =SUM(D13:D15) -> 447348 | E16: =SUM(E13:E15) -> 144974 | F16: =SUM(F13:F15) -> 318588 | G16: =SUM(G13:G15) -> 278000 | H16: =SUM(H13:H15) -> 388000 | I16: =SUM(I13:I15) -> 0 | ... M16: =SUM(M13:M15) -> 0 | N16: =SUM(B16:M16) -> 1960734
W17: =+V17*3 -> 0
A18: Margen de Operación | B18: =+B12-B16 -> 437561 | C18: =+C12-C16 -> 885054 | D18: =+D12-D16 -> 989113 | E18: =+E12-E16 -> 720684 | F18: =+F12-F16 -> 995962 | G18: =+G12-G16 -> 830070 | H18: =+H12-H16 -> 717180 | I18: =+I12-I16 -> 0 | ... M18: =+M12-M16 -> 0 | N18: =SUM(B18:M18) -> 5575624
A20: Fecha: 11.06.2026
A21: Montos expresados en US$
A22: Tasa de demora: USD 20,000
A24: Nota:
A25: (*) Proyección Junio: Un viaje de exportación y dos viajes de cabotaje - uno es NEXA
A26: (**) Proyección Julio: Tres viajes de exportación y un viaje de cabotaje
A28: Provisión por demoras y gastos portuarios de Sandra Galvez.
A29: Gastos portuarios: En el mes de enero se consideró el pago por Light dues 2026

Sheet BT TABLONES JN
A2: B/T TABLONES MARGEN DE OPERACIÓN - PROYECTADO A JULIO 2026
A4: CONCEPTO | B4: ENERO | C4: FEBRERO | D4: MARZO | E4: ABRIL | F4: MAYO | G4: JUNIO (*) | H4: JULIO (**) | I4: AGOSTO | J4: SETIEMBRE | K4: OCTUBRE | L4: NOVIEMBRE | M4: DICIEMBRE | N4: TOTAL
A5: Facturación flete Tablones | B5: 844069.75 | C5: 808897 | D5: 859885 | E5: 814061.19 | F5: 588616 | G5: 1177621.5 | H5: 813255 | N5: =SUM(B5:M5) -> 5906405.5
A6: Reintegro de muellaje Tablones | B6: 53847 | C6: 61757 | D6: 26303 | E6: 55160 | F6: 33567 | G6: =80000 -> 80000 | H6: 40000 | N6: =SUM(B6:M6) -> 350634
A7: Reintegro por segundo ingreso | N7: =SUM(B7:M7) -> 0
A8: Demora Tablones | B8: 273124 | C8: 85125 | D8: 336326 | E8: 188441 | F8: =293507 -> 293507 | G8: 74299.48 | H8: 50000 | N8: =SUM(B8:M8) -> 1300822.5
A9: Otros ingresos | N9: =SUM(B9:M9) -> 0
A10: Ingresos | B10: =+SUM(B5:B9) -> 1171040.8 | C10: =+SUM(C5:C9) -> 955779 | D10: =+SUM(D5:D9) -> 1222514 | E10: =+SUM(E5:E9) -> 1057662.2 | F10: =+SUM(F5:F9) -> 915690 | G10: =+SUM(G5:G9) -> 1331921 | H10: =+SUM(H5:H9) -> 903255 | I10: =+SUM(I5:I9) -> 0 | ... M10: =+SUM(M5:M9) -> 0 | N10: =+SUM(B10:M10) -> 7557861.9
N11: =SUM(B11:M11) -> 0
A12: Otros Ingresos | B12: =+SUM(B11) -> 0 | C12: =+SUM(C1) -> 0 | D12: =+SUM(D1) -> 0 | E12: =+SUM(E11) -> 0 | F12: =+SUM(F11) -> 0 | G12: =+SUM(G11) -> 0 | H12: =+SUM(H11) -> 0 | I12: =+SUM(I11) -> 0 | J12: =+SUM(J11) -> 0 | K12: =+SUM(K11) -> 0 | L12: =+SUM(L11) -> 0 | M12: =+SUM(M11) -> 0 | N12: =+SUM(B12:K12) -> 0
B13: 0 | C13: 0 | D13: 0
A14: Total Ingresos | B14: =+SUM(B10+B12) -> 1171040.8 | C14: =+SUM(C10+C12) -> 955779 | D14: =+SUM(D10+D12) -> 1222514 | E14: =+SUM(E10+E12) -> 1057662.2 | F14: =+SUM(F10+F12) -> 915690 | G14: =+SUM(G10+G12) -> 1331921 | H14: =+SUM(H10+H12) -> 903255 | I14: =+SUM(I10+I12) -> 0 | ... M14: =+SUM(M10+M12) -> 0 | N14: =SUM(B14:M14) -> 7557861.9
A16: Bunker Tablones | B16: 119578 | C16: 127935 | D16: 77788 | E16: 107267 | F16: 138748 | G16: 180000 | H16: 165000 | N16: =SUM(B16:M16) -> 916316
A17: Costos portuarios | B17: 260429 | C17: 317390 | D17: =52458+3450 -> 55908 | E17: 197019 | F17: 111426 | G17: 292000 | H17: 205000 | N17: =SUM(B17:M17) -> 1439172
A18: Costo por demora otras naves | N18: =SUM(B18:M18) -> 0
A19: Otros costos | F19: 1015 | N19: =SUM(B19:M19) -> 1015
A20: Total Egresos | B20: =+SUM(B16:B19) -> 380007 | C20: =+SUM(C16:C19) -> 445325 | D20: =+SUM(D16:D18) -> 133696 | E20: =+E16+E17 -> 304286 | F20: =+SUM(F16:F19) -> 251189 | G20: =+SUM(G16:G18) -> 472000 | H20: =+SUM(H16:H18) -> 370000 | I20: =+SUM(I16:I19) -> 0 | J20: =+SUM(J16:J19) -> 0 | K20: =+SUM(K16:K19) -> 0 | L20: =+SUM(L16:L18) -> 0 | M20: =+SUM(M16:M18) -> 0 | N20: =SUM(B20:M20) -> 2356503
N22: =SUM(B22:M22) -> 0 | R22: Sandra
B23: 0 | C23: 0 | D23: 0 | E23: 0 | G23: 0 | H23: 0 | I23: 0 | J23: 0 | K23: 0 | L23: 0 | M23: 0 | N23: =SUM(B23:M23) -> 0 | P23: 17750 | Q23: 23.6 | R23: =+P23*Q23 -> 418900
B24: =+SUM(B22:B23) -> 0 | C24: =+SUM(C22:C23) -> 0 | D24: =+SUM(D22:D23) -> 0 | E24: =+SUM(E22:E23) -> 0 | F24: =+SUM(F22:F23) -> 0 | G24: =+SUM(G22:G23) -> 0 | H24: =+SUM(H22:H23) -> 0 | I24: =+SUM(I22:I23) -> 0 | ... M24: =+SUM(M22:M23) -> 0 | N24: =SUM(B24:M24) -> 0
A26: Total Egresos | B26: =+SUM(B20+B24) -> 380007 | C26: =+SUM(C20+C24) -> 445325 | D26: =+SUM(D20+D24) -> 133696 | E26: =+SUM(E20+E24) -> 304286 | F26: =+SUM(F20+F24) -> 251189 | G26: =+SUM(G20+G24) -> 472000 | H26: =+SUM(H20+H24) -> 370000 | I26: =+SUM(I20+I24) -> 0 | ... M26: =+SUM(M20+M24) -> 0 | N26: =SUM(B26:M26) -> 2356503
A28: Margen de Operación | B28: =+B14-B26 -> 791033.75 | C28: =+C14-C26 -> 510454 | D28: =+D14-D26 -> 1088818 | E28: =+E14-E26 -> 753376.19 | F28: =+F14-F26 -> 664501 | G28: =+G14-G26 -> 859921.01 | H28: =+H14-H26 -> 533255 | I28: =+I14-I26 -> 0 | ... M28: =+M14-M26 -> 0 | N28: =SUM(B28:M28) -> 5201359
A30: Fecha: 11.06.2026
A31: Montos expresados en US$ | M31: =(334822/2)-10824 -> 156587
A32: Tasa de demora: USD 20,000
A34: Nota:
A35: (*) Proyección a Junio: Cuatro viajes de exportación
A36: (**) Proyección a Julio: Dos viajes de exportación y un viaje de cabotaje
A38: Provisión por demoras y gastos portuarios de Sandra Galvez.
A39: Gastos portuarios: En el mes de enero se consideró el pago por Light dues 2026
B43: 34000 | C43: 44000
B44: 66111 | C44: 76305
B45: =SUM(B43:B44) -> 100111 | C45: =SUM(C43:C44) -> 120305
F46: Mes
A47: 15 Dic - 15 Enero per day (total usd 334,812.20) | B47: =334812.2/31 -> 10800.394 | C47: 44545.938 | F47: 44562 | G47: =+B48+B51 -> 323383.18
A48: 1-15 enero | B48: =+B47*15 -> 162005.9 | C48: 44576.938 | D48: =+C48-C47 -> 31
A50: 15 Ene - 15 Feb per day (total usd 333,513.04) | B50: =333513.04/31 -> 10758.485 | C50: 44576.938
A51: 15 -31 enero | B51: =+B50*15 -> 161377.28 | C51: 44607.938 | D51: =+C51-C50 -> 31
A56: 15 Feb - 15 Mar per day (total usd 129,172.75) | C56: 44607.938
A57: 1-15 febrero | C57: 44635.938 | D57: =+C57-C56 -> 28
...

Sheet BT HUEMUL-CONCON TRADER
A2: B/T HUEMUL - B/T CONCON TRADER MARGEN DE OPERACIÓN - PROYECTADO A JUNIO 2026
A4: CONCEPTO | B4: ENERO | C4: FEBRERO | D4: MARZO | E4: ABRIL | F4: MAYO (*) | G4: JUNIO (**) | J4: SETIEMBRE | K4: OCTUBRE | L4: NOVIEMBRE | M4: DICIEMBRE | N4: TOTAL
A5: Facturación flete Huemul V. 105 y Concon Trader V.166 | F5: 362132 | G5: 289380 | N5: =SUM(B5:M5) -> 651512
A6: Reintegro de muellaje HUEMUL V.105 y Concon Trader V.166 | N6: =SUM(B6:M6) -> 0
A7: Reintegro por segundo ingreso | N7: =SUM(B7:M7) -> 0
A8: Demora Huemul V.105 y Concon Trader V.166 | F8: 110458 | N8: =SUM(B8:M8) -> 110458
A9: Otros ingresos
A10: Ingresos Otros Buques | F10: =+SUM(F5:F9) -> 472590 | G10: =+SUM(G5:G9) -> 289380 | I10: =+SUM(I5:I9) -> 0 | J10: =+SUM(J5:J9) -> 0 | K10: =+SUM(K5:K9) -> 0 | L10: =+SUM(L5:L9) -> 0 | M10: =+SUM(M5:M9) -> 0 | N10: =+SUM(B10:M10) -> 761970
A11: Otros Ingresos Combustible | N11: =SUM(B11:M11) -> 0
A12: Otros Ingresos | F12: =+SUM(F11) -> 0 | G12: =+SUM(G11) -> 0 | I12: =+SUM(I11) -> 0 | J12: =+SUM(J11) -> 0 | K12: =+SUM(K11) -> 0 | L12: =+SUM(L11) -> 0 | M12: =+SUM(M11) -> 0 | N12: =+SUM(B12:K12) -> 0
A14: Total Ingresos | F14: =+SUM(F10+F12) -> 472590 | G14: =+SUM(G10+G12) -> 289380 | I14: =+SUM(I10+I12) -> 0 | J14: =+SUM(J10+J12) -> 0 | K14: =+SUM(K10+K12) -> 0 | L14: =+SUM(L10+L12) -> 0 | M14: =+SUM(M10+M12) -> 0 | N14: =SUM(B14:M14) -> 761970
A16: Bunker | N16: =SUM(B16:M16) -> 0
A17: Costos demora Huemul V.105 y Concon Trader V.166 | F17: 112500 | N17: =SUM(B17:M17) -> 112500
A18: Costo arriendo Huemul V.105 y Concon Trader V. 166 | F18: 417912 | G18: 359800 | N18: =SUM(B18:M18) -> 777712
A19: Otros costos | N19: =SUM(B19:M19) -> 0
A20: Total Egresos | F20: =+F17+F18 -> 530412 | G20: =+SUM(G16:G18) -> 359800 | I20: =+SUM(I16:I19) -> 0 | J20: =+SUM(J16:J19) -> 0 | K20: =+SUM(K16:K19) -> 0 | L20: =+SUM(L16:L18) -> 0 | M20: =+SUM(M16:M18) -> 0 | N20: =SUM(B20:M20) -> 890212
A22: Demora Huemul V.105 Ultranav (aproximada) | F22: 112500 | N22: =SUM(B22:M22) -> 112500
A23: Costos arriendo nave HUEMUL V. 105 (Ultranav) | F23: 417912 | G23: 0 | I23: 0 | J23: 0 | K23: 0 | L23: 0 | M23: 0 | N23: =SUM(B23:M23) -> 417912
A24: Egresos otros buques | F24: =+SUM(F22:F23) -> 530412 | G24: =+SUM(G22:G23) -> 0 | I24: =+SUM(I22:I23) -> 0 | J24: =+SUM(J22:J23) -> 0 | K24: =+SUM(K22:K23) -> 0 | L24: =+SUM(L22:L23) -> 0 | M24: =+SUM(M22:M23) -> 0 | N24: =SUM(B24:M24) -> 530412
A26: Total Egresos | F26: =+F10-F20 -> -57822 | G26: =+SUM(G20+G24) -> 359800 | I26: =+SUM(I20+I24) -> 0 | J26: =+SUM(J20+J24) -> 0 | K26: =+SUM(K20+K24) -> 0 | L26: =+SUM(L20+L24) -> 0 | M26: =+SUM(M20+M24) -> 0 | N26: =SUM(B26:M26) -> 301978
A28: Margen de Operación | F28: =+F26 -> -57822 | G28: =+G14-G26 -> -70420 | I28: =+I14-I26 -> 0 | J28: =+J14-J26 -> 0 | K28: =+K14-K26 -> 0 | L28: =+L14-L26 -> 0 | M28: =+M14-M26 -> 0 | N28: =SUM(B28:M28) -> -128242
A30: Fecha: 11.06.2026
A31: Montos expresados en US$ | M31: =(334822/2)-10824 -> 156587
A34: Nota:
A35: (*) Mayo: B/T Huemul viaje 105 a SPCC ruta Ilo - Mejillones
A36: (**) Proyección a Junio: B/T Concon Trader viaje 166 a SPCC ruta Ilo - Mejillones
B43: 34000 | C43: 44000
B44: 66111 | C44: 76305
B45: =SUM(B43:B44) -> 100111 | C45: =SUM(C43:C44) -> 120305
F46: Mes
A47: 15 Dic - 15 Enero per day (total usd 334,812.20) | B47: =334812.2/31 -> 10800.394 | C47: 44545.938 | F47: 44562 | G47: =+B48+B51 -> 323383.18
A48: 1-15 enero | B48: =+B47*15 -> 162005.9 | C48: 44576.938 | D48: =+C48-C47 -> 31
A50: 15 Ene - 15 Feb per day (total usd 333,513.04) | B50: =333513.04/31 -> 10758.485 | C50: 44576.938
A51: 15 -31 enero | B51: =+B50*15 -> 161377.28 | C51: 44607.938 | D51: =+C51-C50 -> 31
A56: 15 Feb - 15 Mar per day (total usd 129,172.75) | C56: 44607.938
A57: 1-15 febrero | C57: 44635.938 | D57: =+C57-C56 -> 28
B61: 120 | C61: 820 | D61: =+B61*C61 -> 98400
