Workbook

Sheet RESUMEN
B3: B/T TABLONES - CONTRATO SPCC
B4: VOYAGE CALCULATION
B6: CABOTAJE - Ilo - Matarani | C6: Flete actual | E6: T.C.E | F6: P/L
B7: 13,500 TM | C7: 19.01 | E7: =+'ILO-MATARANI'!Q17 -> 47801.347 | F7: =+'ILO-MATARANI'!Q20 -> 133831.98
B9: CABOTAJE - Ilo - San Juan de Marcona | C9: Flete actual | E9: T.C.E | F9: P/L
B10: 13,500 TM | C10: 22.82 | E10: =+'ILO-SAN JUAN DE MARCONA'!Q17 -> 34573.372 | F10: =+'ILO-SAN JUAN DE MARCONA'!Q20 -> 112545.4
B12: EXPORTACIÓN - Ilo - Mejillones | C12: Flete actual | E12: T.C.E | F12: P/L
B13: 13,500 TM | C13: 20.87 | E13: =+'ILO-MEJILLONES'!Q17 -> 28705.63 | F13: =+'ILO-MEJILLONES'!Q20 -> 84367.497
B16: COSTOS PORTUARIOS B/T TABLONES
B17: ILO | C17: 23000
B18: MATARANI | C18: 18000
B19: SAN JUAN DE MARCONA | C19: 44000
B20: MEJILLONES | C20: 32000
B22: Nota:
B23: El valor del combustible que se ha considerado es en base al contrato con SPCC (no el precio actual).

Sheet ILO-MATARANI
B1: Voyage Estimation | G1: Prepared By | H1: JN
P2: Consumption & Duration
B3: Vessel Description | P3: Daily Rate | S3: Total
P4: IFO | Q4: MDO | S4: Days
B5: Name | C5: TABLONES | F5: DWT | G5: 16500 | J5: LOA | P5: 14.5 | Q5: 0 | R5: Sea | S5: =+Q15 -> 0.53840909
B6: Voyage | F6: CBM | J6: Beam | P6: 3.5 | Q6: 0 | R6: Idle | S6: =+(J35)/24 -> 0.54166667
B7: Flag | C7: PERUANA | F7: Built | G7: 2003 | J7: Draft | P7: 3.5 | Q7: 0 | R7: Load | S7: =+K35/24 -> 1.125
P8: 5 | Q8: 0 | R8: Disch. | S8: =+L35/24 -> 1.875
B9: Voyage Type | P9: 0 | Q9: 0 | R9: Clean | S9: 0
P10: 0 | Q10: 0 | R10: Heating
B12: Income | K12: Results
B14: Charterer/Cargo | C14: =IF(V17=1,"Flat Rate",IF(V17=2,"Freight",IF(V17=3,"Lumpsum",))) -> Freight | D14: =IF(C14="Flat Rate","WS","") | E14: Quantity | F14: Unit | G14: Total | H14: Comm. | I14: Net | K14: Income | N14: =+I23 -> 256635 | O14: Duration (d) | Q14: =+Q15+S6+S7+S8 -> 4.0800758 | V14: Flat Rate Worldscale (USD/mt)
B15: SPCC ACIDO | C15: 19.01 | E15: 13500 | F15: MT | G15: =IF(C15="","",IF($C$14="Flat Rate",C15*D15/100*E15,IF($C$14="Freight",C15*E15,IF($C$14="Lumpsum",C15,)))) -> 256635 | I15: =IF(G15="","",+G15*(1-H15)) -> 256635 | K15: Port Costs | N15: =D49 -> 41000 | O15: Sea Days | Q15: =+R35/24 -> 0.53840909 | V15: Freight (USD/Unit)
G16: =IF(C16="","",IF($C$14="Flat Rate",C16*D16/100*E16,IF($C$14="Freight",C16*E16,IF($C$14="Lumpsum",C16,)))) | I16: =IF(G16="","",+G16*(1-H16)) | K16: Bunker Costs | N16: =+S49 -> 20601.884 | O16: Port/Idle Days | Q16: =+S6+S7+S8 -> 3.5416667 | V16: Lumpsum (USD)
G17: =IF(C17="","",IF($C$14="Flat Rate",C17*D17/100*E17,IF($C$14="Freight",C17*E17,IF($C$14="Lumpsum",C17,)))) | I17: =IF(G17="","",+G17*(1-H17)) | K17: Other Costs | N17: =+G62 -> 0 | O17: TCE (US$/d) | Q17: =+N18/Q14 -> 47801.347 | V17: 2
G18: =IF(C18="","",IF($C$14="Flat Rate",C18*D18/100*E18,IF($C$14="Freight",C18*E18,IF($C$14="Lumpsum",C18,)))) | I18: =IF(G18="","",+G18*(1-H18)) | K18: Voyage Result (US$) | N18: =+N14-N15-N16-N17 -> 195033.12 | O18: TCE Req. (US$/d) | Q18: 15000
G19: =IF(C19="","",IF($C$14="Flat Rate",C19*D19/100*E19,IF($C$14="Freight",C19*E19,IF($C$14="Lumpsum",C19,)))) | I19: =IF(G19="","",+G19*(1-H19)) | O19: PCM (US$) | Q19: =Q17*30.42 -> 1454117
G20: =IF(C20="","",IF($C$14="Flat Rate",C20*D20/100*E20,IF($C$14="Freight",C20*E20,IF($C$14="Lumpsum",C20,)))) | I20: =IF(G20="","",+G20*(1-H20)) | O20: P/L (US$) | Q20: =+N18-Q18*Q14 -> 133831.98
G22: =IF(C22="","",IF($C$14="Flat Rate",C22*D22/100*E22,IF($C$14="Freight",C22*E22,IF($C$14="Lumpsum",C22,)))) | I22: =IF(G22="","",+G22*(1-H22))
G23: Total Freight Income US$ | I23: =SUM(I15:I22) -> 256635
B25: Voyage Program
B27: Port | D27: Arrival | G27: Quantity | H27: Rate | I27: Laytime | J27: Port Times (hrs.) | N27: Departure | P27: Voyage | S27: Weather
D28: Day | F28: hr | G28: (mt / m3) | H28: per hr. | I28: (hrs) | J28: Other | K28: Load | L28: Disch. | M28: Total | N28: Day | O28: hr | P28: Dist. | Q28: Speed | R28: Sailing | S28: Factor
B29: ILO | J29: 1 | M29: =IF(B29=0,"",SUM(J29:L29)) -> 1 | N29: 41061.5 | O29: =IF(B29=0,"",HOUR(N29)) -> 12
B30: ILO | D30: =IF(B30=0,"",+J29/24+N29+((R30)/24)) -> 41061.811 | F30: =IF(B30=0,"",HOUR(D30)) -> 19 | G30: =+E15 -> 13500 | H30: 500 | J30: 6 | K30: =IF(B30=0,"",IF(H30=0,IF(G30>0,I30,0),IF(G30>0,G30/H30,0))) -> 27 | L30: =IF(B30=0,"",IF(H30=0,IF(G30<0,I30,0),IF(G30<0,G30/H30,0))) -> 0 | M30: =IF(B30=0,"",SUM(J30:L30)) -> 33 | N30: =IF(B30=0,"",(D30+(K30+L30+J30)/24)) -> 41063.186 | O30: =IF(B30=0,"",HOUR(N30)) -> 4 | P30: 69 | Q30: 11 | R30: =IF(B30=0,"",IF(Q30=0,0,+P30*(1+S30)/Q30)) -> 6.4609091 | S30: 0.03
B31: MATARANI | D31: =IF(B31=0,"",+J30/24+N30+((R31)/24)) -> 41063.705 | F31: =IF(B31=0,"",HOUR(D31)) -> 16 | G31: =-E15 -> -13500 | H31: -300 | J31: 6 | K31: =IF(B31=0,"",IF(H31=0,IF(G31>0,I31,0),IF(G31>0,G31/H31,0))) -> 0 | L31: =IF(B31=0,"",IF(H31=0,IF(G31<0,I31,0),IF(G31<0,G31/H31,0))) -> 45 | M31: =IF(B31=0,"",SUM(J31:L31)) -> 51 | N31: =IF(B31=0,"",(D31+(K31+L31+J31)/24)) -> 41065.83 | O31: =IF(B31=0,"",HOUR(N31)) -> 19 | P31: 69 | Q31: =IF(B31=0,"",Q30) -> 11 | R31: =IF(B31=0,"",IF(Q31=0,0,+P31*(1+S31)/Q31)) -> 6.4609091 | S31: 0.03
B32: ILO
D34: =IF(B34=0,"",+#REF!+((R34)/24)) | F34: =IF(B34=0,"",HOUR(D34)) | K34: =IF(B34=0,"",IF(H34=0,IF(G34>0,I34,0),IF(G34>0,G34/H34,0))) | L34: =IF(B34=0,"",IF(H34=0,IF(G34<0,I34,0),IF(G34<0,G34/H34,0))) | M34: =IF(B34=0,"",SUM(J34:L34)) | N34: =IF(B34=0,"",(D34+(K34+L34+J34)/24)) | O34: =IF(B34=0,"",HOUR(N34)) | Q34: =IF(B34=0,"",#REF!) | R34: =IF(B34=0,"",IF(Q34=0,0,+P34*(1+S34)/Q34))
B35: Total | G35: =SUM(G29:G34) -> 0 | I35: =SUM(I29:I34) -> 0 | J35: =SUM(J29:J34) -> 13 | K35: =SUM(K29:K34) -> 27 | L35: =SUM(L29:L34) -> 45 | M35: =SUM(M29:M34) -> 85 | P35: =SUM(P29:P34) -> 138 | R35: =SUM(R29:R34) -> 12.921818
B37: Port Expenses | E37: Bunker Expenses
B39: Port | D39: Agency | E39: Arrival ROB | G39: Purch.Quantity | I39: Purch. Price | K39: Depart. ROB | M39: Port Consumption | O39: Sailing Cons. | Q39: Average Price | S39: Bunk.
E40: IFO | F40: MDO | G40: IFO | H40: MDO | I40: IFO | J40: MDO | K40: IFO | L40: MDO | M40: IFO | N40: MDO | O40: IFO | P40: MDO | Q40: IFO | R40: MDO | S40: Cost
B41: ILO | K41: 1000 | L41: 100 | M41: =IF(B29=0,"",+($P$6*J29+$P$7*K29+$P$8*L29)/24) -> 0.14583333 | N41: =IF(B30=0,"",(+$Q$6*J30+$Q$7*K30+$Q$8*L30)/24) -> 0 | Q41: 895.14 | R41: 0 | S41: =IF(B30=0,"",(M41+O41)*Q41+(N41+P41)*R41) -> 130.54125
B42: ILO | D42: 23000 | E42: =IF(B31=0,"",+K41-O42) -> 996.09653 | F42: =IF(B31=0,"",+L41-P42) -> 100 | K42: =IF(B29=0,"",+E42+G42-M42) -> 991.28403 | L42: =IF(B29=0,"",+F42+H42-N42) -> 100 | M42: =IF(B30=0,"",+($P$6*J30+$P$7*K30+$P$8*L30)/24) -> 4.8125 | N42: =IF(B31=0,"",(+$Q$6*J31+$Q$7*K31+$Q$8*L31)/24) -> 0 | O42: =IF(B30=0,"",(R30/24*$P$5)) -> 3.9034659 | P42: =IF(B29=0,"",+R29/24*$Q$5) -> 0 | Q42: =IF(B31=0,"",+(E42*Q41+I42*G42)/(G42+E42)) -> 895.14 | R42: =IF(B31=0,"",+(J42*H42+L41*R41)/(H42+L41)) -> 0 | S42: =IF(B31=0,"",(M42+O42)*Q42+(N42+P42)*R42) -> 7802.0097
B43: MATARANI | D43: 18000 | E43: =IF(B32=0,"",+K42-O43) -> 987.38057 | F43: =IF(B32=0,"",+L42-P43) -> 100 | K43: =IF(B30=0,"",+E43+G43-M43) -> 977.13057 | L43: =IF(B30=0,"",+F43+H43-N43) -> 100 | M43: =IF(B31=0,"",+($P$6*J31+$P$7*K31+$P$8*L31)/24) -> 10.25 | N43: =IF(B32=0,"",(+$Q$6*J32+$Q$7*K32+$Q$8*L32)/24) -> 0 | O43: =IF(B31=0,"",(R31/24*$P$5)) -> 3.9034659 | P43: =IF(B30=0,"",+R30/24*$Q$5) -> 0 | Q43: =IF(B32=0,"",+(E43*Q42+I43*G43)/(G43+E43)) -> 895.14 | R43: =IF(B32=0,"",+(J43*H43+L42*R42)/(H43+L42)) -> 0 | S43: =IF(B32=0,"",(M43+O43)*Q43+(N43+P43)*R43) -> 12669.333
B44: ILO
B49: Total Agency US$ | D49: =SUM(D41:D48) -> 41000 | M49: =SUM(M41:M48) -> 15.208333 | N49: =SUM(N41:N48) -> 0 | O49: =SUM(O41:O48) -> 7.8069318 | P49: =SUM(P41:P48) -> 0 | R49: Bunkers US$ | S49: =SUM(S41:S48) -> 20601.884
M50: Total Bunker Cons. (Incl. Cleaning & Heating) | N50: =+O49+M49+C60+C61 -> 23.015265 | O50: =+P49+N49+D60+D61 -> 0
B52: Other Expenses
B54: Description | G54: Total
...

Sheet ILO-SAN JUAN DE MARCONA
B1: Voyage Estimation | G1: Prepared By | H1: JN
P2: Consumption & Duration
B3: Vessel Description | P3: Daily Rate | S3: Total
P4: IFO | Q4: MDO | S4: Days
B5: Name | C5: TABLONES | F5: DWT | G5: 16500 | J5: LOA | P5: 14.5 | Q5: 0 | R5: Sea | S5: =+Q15 -> 2.2082576
B6: Voyage | F6: CBM | J6: Beam | P6: 3.5 | Q6: 0 | R6: Idle | S6: =+(J35)/24 -> 0.54166667
B7: Flag | C7: PERUANA | F7: Built | G7: 2003 | J7: Draft | P7: 3.5 | Q7: 0 | R7: Load | S7: =+K35/24 -> 1.125
P8: 5 | Q8: 0 | R8: Disch. | S8: =+L35/24 -> 1.875
B9: Voyage Type | P9: 0 | Q9: 0 | R9: Clean | S9: 0
P10: 0 | Q10: 0 | R10: Heating
B12: Income | K12: Results
B14: Charterer/Cargo | C14: =IF(V17=1,"Flat Rate",IF(V17=2,"Freight",IF(V17=3,"Lumpsum",))) -> Freight | D14: =IF(C14="Flat Rate","WS","") | E14: Quantity | F14: Unit | G14: Total | H14: Comm. | I14: Net | K14: Income | N14: =+I23 -> 308070 | O14: Duration (d) | Q14: =+Q15+S6+S7+S8 -> 5.7499242 | V14: Flat Rate Worldscale (USD/mt)
B15: SPCC ACIDO | C15: 22.82 | E15: 13500 | F15: MT | G15: =IF(C15="","",IF($C$14="Flat Rate",C15*D15/100*E15,IF($C$14="Freight",C15*E15,IF($C$14="Lumpsum",C15,)))) -> 308070 | I15: =IF(G15="","",+G15*(1-H15)) -> 308070 | K15: Port Costs | N15: =D46 -> 67000 | O15: Sea Days | Q15: =+R35/24 -> 2.2082576 | V15: Freight (USD/Unit)
G16: =IF(C16="","",IF($C$14="Flat Rate",C16*D16/100*E16,IF($C$14="Freight",C16*E16,IF($C$14="Lumpsum",C16,)))) | I16: =IF(G16="","",+G16*(1-H16)) | K16: Bunker Costs | N16: =+S46 -> 42275.733 | O16: Port/Idle Days | Q16: =+S6+S7+S8 -> 3.5416667 | V16: Lumpsum (USD)
G17: =IF(C17="","",IF($C$14="Flat Rate",C17*D17/100*E17,IF($C$14="Freight",C17*E17,IF($C$14="Lumpsum",C17,)))) | I17: =IF(G17="","",+G17*(1-H17)) | K17: Other Costs | N17: =+G59 -> 0 | O17: TCE (US$/d) | Q17: =+N18/Q14 -> 34573.372 | V17: 2
G18: =IF(C18="","",IF($C$14="Flat Rate",C18*D18/100*E18,IF($C$14="Freight",C18*E18,IF($C$14="Lumpsum",C18,)))) | I18: =IF(G18="","",+G18*(1-H18)) | K18: Voyage Result (US$) | N18: =+N14-N15-N16-N17 -> 198794.27 | O18: TCE Req. (US$/d) | Q18: 15000
G19: =IF(C19="","",IF($C$14="Flat Rate",C19*D19/100*E19,IF($C$14="Freight",C19*E19,IF($C$14="Lumpsum",C19,)))) | I19: =IF(G19="","",+G19*(1-H19)) | O19: PCM (US$) | Q19: =Q17*30.42 -> 1051722
G20: =IF(C20="","",IF($C$14="Flat Rate",C20*D20/100*E20,IF($C$14="Freight",C20*E20,IF($C$14="Lumpsum",C20,)))) | I20: =IF(G20="","",+G20*(1-H20)) | O20: P/L (US$) | Q20: =+N18-Q18*Q14 -> 112545.4
G22: =IF(C22="","",IF($C$14="Flat Rate",C22*D22/100*E22,IF($C$14="Freight",C22*E22,IF($C$14="Lumpsum",C22,)))) | I22: =IF(G22="","",+G22*(1-H22))
G23: Total Freight Income US$ | I23: =SUM(I15:I22) -> 308070
B25: Voyage Program
B27: Port | D27: Arrival | G27: Quantity | H27: Rate | I27: Laytime | J27: Port Times (hrs.) | N27: Departure | P27: Voyage | S27: Weather
D28: Day | F28: hr | G28: (mt / m3) | H28: per hr. | I28: (hrs) | J28: Other | K28: Load | L28: Disch. | M28: Total | N28: Day | O28: hr | P28: Dist. | Q28: Speed | R28: Sailing | S28: Factor
B29: ILO | J29: 1 | M29: =IF(B29=0,"",SUM(J29:L29)) -> 1 | N29: 41061.5 | O29: =IF(B29=0,"",HOUR(N29)) -> 12
B30: ILO | D30: =IF(B30=0,"",+J29/24+N29+((R30)/24)) -> 41062.646 | F30: =IF(B30=0,"",HOUR(D30)) -> 15 | G30: =+E15 -> 13500 | H30: 500 | J30: 6 | K30: =IF(B30=0,"",IF(H30=0,IF(G30>0,I30,0),IF(G30>0,G30/H30,0))) -> 27 | L30: =IF(B30=0,"",IF(H30=0,IF(G30<0,I30,0),IF(G30<0,G30/H30,0))) -> 0 | M30: =IF(B30=0,"",SUM(J30:L30)) -> 33 | N30: =IF(B30=0,"",(D30+(K30+L30+J30)/24)) -> 41064.021 | O30: =IF(B30=0,"",HOUR(N30)) -> 0 | P30: 283 | Q30: 11 | R30: =IF(B30=0,"",IF(Q30=0,0,+P30*(1+S30)/Q30)) -> 26.499091 | S30: 0.03
B31: SAN JUAN DE MARCONA | D31: =IF(B31=0,"",+J30/24+N30+((R31)/24)) -> 41065.375 | F31: =IF(B31=0,"",HOUR(D31)) -> 8 | G31: =-E15 -> -13500 | H31: -300 | J31: 6 | K31: =IF(B31=0,"",IF(H31=0,IF(G31>0,I31,0),IF(G31>0,G31/H31,0))) -> 0 | L31: =IF(B31=0,"",IF(H31=0,IF(G31<0,I31,0),IF(G31<0,G31/H31,0))) -> 45 | M31: =IF(B31=0,"",SUM(J31:L31)) -> 51 | N31: =IF(B31=0,"",(D31+(K31+L31+J31)/24)) -> 41067.5 | O31: =IF(B31=0,"",HOUR(N31)) -> 11 | P31: 283 | Q31: =IF(B31=0,"",Q30) -> 11 | R31: =IF(B31=0,"",IF(Q31=0,0,+P31*(1+S31)/Q31)) -> 26.499091 | S31: 0.03
B32: ILO | P32: 0
D34: =IF(B34=0,"",+#REF!+((R34)/24)) | F34: =IF(B34=0,"",HOUR(D34)) | K34: =IF(B34=0,"",IF(H34=0,IF(G34>0,I34,0),IF(G34>0,G34/H34,0))) | L34: =IF(B34=0,"",IF(H34=0,IF(G34<0,I34,0),IF(G34<0,G34/H34,0))) | M34: =IF(B34=0,"",SUM(J34:L34)) | N34: =IF(B34=0,"",(D34+(K34+L34+J34)/24)) | O34: =IF(B34=0,"",HOUR(N34)) | Q34: =IF(B34=0,"",#REF!) | R34: =IF(B34=0,"",IF(Q34=0,0,+P34*(1+S34)/Q34))
B35: Total | G35: =SUM(G29:G34) -> 0 | I35: =SUM(I29:I34) -> 0 | J35: =SUM(J29:J34) -> 13 | K35: =SUM(K29:K34) -> 27 | L35: =SUM(L29:L34) -> 45 | M35: =SUM(M29:M34) -> 85 | P35: =SUM(P29:P34) -> 566 | R35: =SUM(R29:R34) -> 52.998182
B37: Port Expenses | E37: Bunker Expenses
B39: Port | D39: Agency | E39: Arrival ROB | G39: Purch.Quantity | I39: Purch. Price | K39: Depart. ROB | M39: Port Consumption | O39: Sailing Cons. | Q39: Average Price | S39: Bunk.
E40: IFO | F40: MDO | G40: IFO | H40: MDO | I40: IFO | J40: MDO | K40: IFO | L40: MDO | M40: IFO | N40: MDO | O40: IFO | P40: MDO | Q40: IFO | R40: MDO | S40: Cost
B41: ILO | K41: 1000 | L41: 100 | M41: =IF(B29=0,"",+($P$6*J29+$P$7*K29+$P$8*L29)/24) -> 0.14583333 | N41: =IF(B30=0,"",(+$Q$6*J30+$Q$7*K30+$Q$8*L30)/24) -> 0 | Q41: 895.14 | R41: 0 | S41: =IF(B30=0,"",(M41+O41)*Q41+(N41+P41)*R41) -> 130.54125
B42: ILO | D42: 23000 | E42: =IF(B31=0,"",+K41-O42) -> 983.99013 | F42: =IF(B31=0,"",+L41-P42) -> 100 | K42: =IF(B29=0,"",+E42+G42-M42) -> 979.17763 | L42: =IF(B29=0,"",+F42+H42-N42) -> 100 | M42: =IF(B30=0,"",+($P$6*J30+$P$7*K30+$P$8*L30)/24) -> 4.8125 | N42: =IF(B31=0,"",(+$Q$6*J31+$Q$7*K31+$Q$8*L31)/24) -> 0 | O42: =IF(B30=0,"",(R30/24*$P$5)) -> 16.009867 | P42: =IF(B29=0,"",+R29/24*$Q$5) -> 0 | Q42: =IF(B31=0,"",+(E42*Q41+I42*G42)/(G42+E42)) -> 895.14 | R42: =IF(B31=0,"",+(J42*H42+L41*R41)/(H42+L41)) -> 0 | S42: =IF(B31=0,"",(M42+O42)*Q42+(N42+P42)*R42) -> 18638.934
B43: SAN JUAN DE MARCONA | D43: 44000 | E43: =IF(B32=0,"",+K42-O43) -> 963.16777 | F43: =IF(B32=0,"",+L42-P43) -> 100 | K43: =IF(B30=0,"",+E43+G43-M43) -> 952.91777 | L43: =IF(B30=0,"",+F43+H43-N43) -> 100 | M43: =IF(B31=0,"",+($P$6*J31+$P$7*K31+$P$8*L31)/24) -> 10.25 | N43: =IF(B32=0,"",(+$Q$6*J32+$Q$7*K32+$Q$8*L32)/24) -> 0 | O43: =IF(B31=0,"",(R31/24*$P$5)) -> 16.009867 | P43: =IF(B30=0,"",+R30/24*$Q$5) -> 0 | Q43: =IF(B32=0,"",+(E43*Q42+I43*G43)/(G43+E43)) -> 895.14 | R43: =IF(B32=0,"",+(J43*H43+L42*R42)/(H43+L42)) -> 0 | S43: =IF(B32=0,"",(M43+O43)*Q43+(N43+P43)*R43) -> 23506.258
B44: ILO
B46: Total Agency US$ | D46: =SUM(D41:D45) -> 67000 | M46: =SUM(M41:M45) -> 15.208333 | N46: =SUM(N41:N45) -> 0 | O46: =SUM(O41:O45) -> 32.019735 | P46: =SUM(P41:P45) -> 0 | R46: Bunkers US$ | S46: =SUM(S41:S45) -> 42275.733
M47: Total Bunker Cons. (Incl. Cleaning & Heating) | N47: =+O46+M46+C57+C58 -> 47.228068 | O47: =+P46+N46+D57+D58 -> 0
B49: Other Expenses
B51: Description | G51: Total
...

Sheet ILO-MEJILLONES
B1: Voyage Estimation | G1: Prepared By | H1: JN
P2: Consumption & Duration
B3: Vessel Description | P3: Daily Rate | S3: Total
P4: IFO | Q4: MDO | S4: Days
B5: Name | C5: TABLONES | F5: DWT | G5: 16500 | J5: LOA | P5: 14.5 | Q5: 0 | R5: Sea | S5: =+Q15 -> 2.6140152
B6: Voyage | F6: CBM | J6: Beam | P6: 3.5 | Q6: 0 | R6: Idle | S6: =+(J35)/24 -> 0.54166667
B7: Flag | C7: PERUANA | F7: Built | G7: 2003 | J7: Draft | P7: 3.5 | Q7: 0 | R7: Load | S7: =+K35/24 -> 1.125
P8: 5 | Q8: 0 | R8: Disch. | S8: =+L35/24 -> 1.875
B9: Voyage Type | P9: 0 | Q9: 0 | R9: Clean | S9: 0
P10: 0 | Q10: 0 | R10: Heating
B12: Income | K12: Results
B14: Charterer/Cargo | C14: =IF(V17=1,"Flat Rate",IF(V17=2,"Freight",IF(V17=3,"Lumpsum",))) -> Freight | D14: =IF(C14="Flat Rate","WS","") | E14: Quantity | F14: Unit | G14: Total | H14: Comm. | I14: Net | K14: Income | N14: =+I23 -> 281745 | O14: Duration (d) | Q14: =+Q15+S6+S7+S8 -> 6.1556818 | V14: Flat Rate Worldscale (USD/mt)
B15: SPCC ACIDO | C15: 20.87 | E15: 13500 | F15: MT | G15: =IF(C15="","",IF($C$14="Flat Rate",C15*D15/100*E15,IF($C$14="Freight",C15*E15,IF($C$14="Lumpsum",C15,)))) -> 281745 | I15: =IF(G15="","",+G15*(1-H15)) -> 281745 | K15: Port Costs | N15: =D46 -> 55000 | O15: Sea Days | Q15: =+R35/24 -> 2.6140152 | V15: Freight (USD/Unit)
G16: =IF(C16="","",IF($C$14="Flat Rate",C16*D16/100*E16,IF($C$14="Freight",C16*E16,IF($C$14="Lumpsum",C16,)))) | I16: =IF(G16="","",+G16*(1-H16)) | K16: Bunker Costs | N16: =+S46 -> 47542.276 | O16: Port/Idle Days | Q16: =+S6+S7+S8 -> 3.5416667 | V16: Lumpsum (USD)
G17: =IF(C17="","",IF($C$14="Flat Rate",C17*D17/100*E17,IF($C$14="Freight",C17*E17,IF($C$14="Lumpsum",C17,)))) | I17: =IF(G17="","",+G17*(1-H17)) | K17: Other Costs | N17: =+G59 -> 2500 | O17: TCE (US$/d) | Q17: =+N18/Q14 -> 28705.63 | V17: 2
G18: =IF(C18="","",IF($C$14="Flat Rate",C18*D18/100*E18,IF($C$14="Freight",C18*E18,IF($C$14="Lumpsum",C18,)))) | I18: =IF(G18="","",+G18*(1-H18)) | K18: Voyage Result (US$) | N18: =+N14-N15-N16-N17 -> 176702.72 | O18: TCE Req. (US$/d) | Q18: 15000
G19: =IF(C19="","",IF($C$14="Flat Rate",C19*D19/100*E19,IF($C$14="Freight",C19*E19,IF($C$14="Lumpsum",C19,)))) | I19: =IF(G19="","",+G19*(1-H19)) | O19: PCM (US$) | Q19: =Q17*30.42 -> 873225.26
G20: =IF(C20="","",IF($C$14="Flat Rate",C20*D20/100*E20,IF($C$14="Freight",C20*E20,IF($C$14="Lumpsum",C20,)))) | I20: =IF(G20="","",+G20*(1-H20)) | O20: P/L (US$) | Q20: =+N18-Q18*Q14 -> 84367.497
G22: =IF(C22="","",IF($C$14="Flat Rate",C22*D22/100*E22,IF($C$14="Freight",C22*E22,IF($C$14="Lumpsum",C22,)))) | I22: =IF(G22="","",+G22*(1-H22))
G23: Total Freight Income US$ | I23: =SUM(I15:I22) -> 281745
B25: Voyage Program
B27: Port | D27: Arrival | G27: Quantity | H27: Rate | I27: Laytime | J27: Port Times (hrs.) | N27: Departure | P27: Voyage | S27: Weather
D28: Day | F28: hr | G28: (mt / m3) | H28: per hr. | I28: (hrs) | J28: Other | K28: Load | L28: Disch. | M28: Total | N28: Day | O28: hr | P28: Dist. | Q28: Speed | R28: Sailing | S28: Factor
B29: ILO | J29: 1 | M29: =IF(B29=0,"",SUM(J29:L29)) -> 1 | N29: 41061.5 | O29: =IF(B29=0,"",HOUR(N29)) -> 12
B30: ILO | D30: =IF(B30=0,"",+J29/24+N29+((R30)/24)) -> 41062.849 | F30: =IF(B30=0,"",HOUR(D30)) -> 20 | G30: =+E15 -> 13500 | H30: 500 | J30: 6 | K30: =IF(B30=0,"",IF(H30=0,IF(G30>0,I30,0),IF(G30>0,G30/H30,0))) -> 27 | L30: =IF(B30=0,"",IF(H30=0,IF(G30<0,I30,0),IF(G30<0,G30/H30,0))) -> 0 | M30: =IF(B30=0,"",SUM(J30:L30)) -> 33 | N30: =IF(B30=0,"",(D30+(K30+L30+J30)/24)) -> 41064.224 | O30: =IF(B30=0,"",HOUR(N30)) -> 5 | P30: 335 | Q30: 11 | R30: =IF(B30=0,"",IF(Q30=0,0,+P30*(1+S30)/Q30)) -> 31.368182 | S30: 0.03
B31: MEJILLONES | D31: =IF(B31=0,"",+J30/24+N30+((R31)/24)) -> 41065.781 | F31: =IF(B31=0,"",HOUR(D31)) -> 18 | G31: =-E15 -> -13500 | H31: -300 | J31: 6 | K31: =IF(B31=0,"",IF(H31=0,IF(G31>0,I31,0),IF(G31>0,G31/H31,0))) -> 0 | L31: =IF(B31=0,"",IF(H31=0,IF(G31<0,I31,0),IF(G31<0,G31/H31,0))) -> 45 | M31: =IF(B31=0,"",SUM(J31:L31)) -> 51 | N31: =IF(B31=0,"",(D31+(K31+L31+J31)/24)) -> 41067.906 | O31: =IF(B31=0,"",HOUR(N31)) -> 21 | P31: 335 | Q31: =IF(B31=0,"",Q30) -> 11 | R31: =IF(B31=0,"",IF(Q31=0,0,+P31*(1+S31)/Q31)) -> 31.368182 | S31: 0.03
B32: ILO | P32: 0
D34: =IF(B34=0,"",+#REF!+((R34)/24)) | F34: =IF(B34=0,"",HOUR(D34)) | K34: =IF(B34=0,"",IF(H34=0,IF(G34>0,I34,0),IF(G34>0,G34/H34,0))) | L34: =IF(B34=0,"",IF(H34=0,IF(G34<0,I34,0),IF(G34<0,G34/H34,0))) | M34: =IF(B34=0,"",SUM(J34:L34)) | N34: =IF(B34=0,"",(D34+(K34+L34+J34)/24)) | O34: =IF(B34=0,"",HOUR(N34)) | Q34: =IF(B34=0,"",#REF!) | R34: =IF(B34=0,"",IF(Q34=0,0,+P34*(1+S34)/Q34))
B35: Total | G35: =SUM(G29:G34) -> 0 | I35: =SUM(I29:I34) -> 0 | J35: =SUM(J29:J34) -> 13 | K35: =SUM(K29:K34) -> 27 | L35: =SUM(L29:L34) -> 45 | M35: =SUM(M29:M34) -> 85 | P35: =SUM(P29:P34) -> 670 | R35: =SUM(R29:R34) -> 62.736364
B37: Port Expenses | E37: Bunker Expenses
B39: Port | D39: Agency | E39: Arrival ROB | G39: Purch.Quantity | I39: Purch. Price | K39: Depart. ROB | M39: Port Consumption | O39: Sailing Cons. | Q39: Average Price | S39: Bunk.
E40: IFO | F40: MDO | G40: IFO | H40: MDO | I40: IFO | J40: MDO | K40: IFO | L40: MDO | M40: IFO | N40: MDO | O40: IFO | P40: MDO | Q40: IFO | R40: MDO | S40: Cost
B41: ILO | K41: 1000 | L41: 100 | M41: =IF(B29=0,"",+($P$6*J29+$P$7*K29+$P$8*L29)/24) -> 0.14583333 | N41: =IF(B30=0,"",(+$Q$6*J30+$Q$7*K30+$Q$8*L30)/24) -> 0 | Q41: 895.14 | R41: 0 | S41: =IF(B30=0,"",(M41+O41)*Q41+(N41+P41)*R41) -> 130.54125
B42: ILO | D42: 23000 | E42: =IF(B31=0,"",+K41-O42) -> 981.04839 | F42: =IF(B31=0,"",+L41-P42) -> 100 | K42: =IF(B29=0,"",+E42+G42-M42) -> 976.23589 | L42: =IF(B29=0,"",+F42+H42-N42) -> 100 | M42: =IF(B30=0,"",+($P$6*J30+$P$7*K30+$P$8*L30)/24) -> 4.8125 | N42: =IF(B31=0,"",(+$Q$6*J31+$Q$7*K31+$Q$8*L31)/24) -> 0 | O42: =IF(B30=0,"",(R30/24*$P$5)) -> 18.95161 | P42: =IF(B29=0,"",+R29/24*$Q$5) -> 0 | Q42: =IF(B31=0,"",+(E42*Q41+I42*G42)/(G42+E42)) -> 895.14 | R42: =IF(B31=0,"",+(J42*H42+L41*R41)/(H42+L41)) -> 0 | S42: =IF(B31=0,"",(M42+O42)*Q42+(N42+P42)*R42) -> 21272.205
B43: MEJILLONES | D43: 32000 | E43: =IF(B32=0,"",+K42-O43) -> 957.28428 | F43: =IF(B32=0,"",+L42-P43) -> 100 | K43: =IF(B30=0,"",+E43+G43-M43) -> 947.03428 | L43: =IF(B30=0,"",+F43+H43-N43) -> 100 | M43: =IF(B31=0,"",+($P$6*J31+$P$7*K31+$P$8*L31)/24) -> 10.25 | N43: =IF(B32=0,"",(+$Q$6*J32+$Q$7*K32+$Q$8*L32)/24) -> 0 | O43: =IF(B31=0,"",(R31/24*$P$5)) -> 18.95161 | P43: =IF(B30=0,"",+R30/24*$Q$5) -> 0 | Q43: =IF(B32=0,"",+(E43*Q42+I43*G43)/(G43+E43)) -> 895.14 | R43: =IF(B32=0,"",+(J43*H43+L42*R42)/(H43+L42)) -> 0 | S43: =IF(B32=0,"",(M43+O43)*Q43+(N43+P43)*R43) -> 26139.529
B44: ILO
B46: Total Agency US$ | D46: =SUM(D41:D45) -> 55000 | M46: =SUM(M41:M45) -> 15.208333 | N46: =SUM(N41:N45) -> 0 | O46: =SUM(O41:O45) -> 37.90322 | P46: =SUM(P41:P45) -> 0 | R46: Bunkers US$ | S46: =SUM(S41:S45) -> 47542.276
M47: Total Bunker Cons. (Incl. Cleaning & Heating) | N47: =+O46+M46+C57+C58 -> 53.111553 | O47: =+P46+N46+D57+D58 -> 0
B49: Other Expenses
B51: Description | G51: Total
...
