Workbook
Name cr_control_presupuesto_consolidado: [1]Consolidado!#REF!

Sheet Presentacion

Sheet PETRAL
Z1: =+MONTH(B3) -> 5
B2: Control Presupuestal
B3: 46143 | D3: NAVIERA PETRAL
Q5: REAL | R5: PRESUP. | V5: PPTO. | X5: Real Acum.
B6: (US$ Dólares) | D6: ENE | E6: FEB | F6: MAR | G6: ABR | H6: MAY | I6: JUN | J6: JUL | K6: AGO | L6: SET | M6: OCT | N6: NOV | O6: DIC | Q6: ACUMUL. | R6: ACUMUL. | S6: VARIACION | T6: % | V6: ANUAL | X6: =+B3-365 -> 45778
B8: VENTAS | D8: 1722066.9 | E8: 2111191.9 | F8: 2658974.7 | G8: 1923319.5 | H8: 2702829.5 | I8: 0 | J8: 0 | K8: 0 | L8: 0 | M8: 0 | N8: 0 | O8: 0 | Q8: 11118382 | R8: 9709260 | S8: 1409122.5 | T8: 14.513181 | V8: 22433750 | X8: 8456501.7
A9: * HIRE | B9: HIRE | D9: 1041229.4 | E9: 1827318.9 | F9: 1992698.2 | G9: 1361976.8 | H9: 2170959.6 | I9: 0 | J9: 0 | K9: 0 | L9: 0 | M9: 0 | N9: 0 | O9: 0 | Q9: 8394183 | R9: 7732260 | S9: 661923.05 | T9: 8.5605379 | V9: 18193750 | X9: 6133555
A10: * VENTAS TERCEROS | B10: VENTA DE TERCEROS | D10: 0 | E10: 0 | F10: 0 | G10: 0 | H10: 0 | I10: 0 | J10: 0 | K10: 0 | L10: 0 | M10: 0 | N10: 0 | O10: 0 | Q10: 0 | R10: 0 | S10: 0 | T10: 0 | V10: 0 | X10: 0
A11: * DEMORAS | B11: DEMORAS | D11: 604689.25 | E11: 215350 | F11: 562537.01 | G11: 484964.72 | H11: 465646.06 | I11: 0 | J11: 0 | K11: 0 | L11: 0 | M11: 0 | N11: 0 | O11: 0 | Q11: 2333187 | R11: 1610000 | S11: 723187.04 | T11: 44.91845 | V11: 3460000 | X11: 2034225.3
A12: * INGRESOS DE PUERTO | B12: INGRESOS DE PUERTO | D12: 76148.21 | E12: 68522.9 | F12: 103739.51 | G12: 76377.98 | H12: 66223.77 | I12: 0 | J12: 0 | K12: 0 | L12: 0 | M12: 0 | N12: 0 | O12: 0 | Q12: 391012.37 | R12: 367000 | S12: 24012.37 | T12: 6.5428801 | V12: 780000 | X12: 288721.44
A13: 703117 OTROS ING OPERAC E | B13: OTROS INGRESOS | D13: 0 | E13: 0 | F13: 0 | G13: 0 | H13: 0 | I13: 0 | J13: 0 | K13: 0 | L13: 0 | M13: 0 | N13: 0 | O13: 0 | Q13: 0 | R13: 0 | S13: 0 | T13: 0 | V13: 0 | X13: 0
B15: COSTOS DIRECTOS | D15: -493471.6 | E15: -715684.56 | F15: -581044.39 | G15: -449259.96 | H15: -682277.99 | I15: 0 | J15: 0 | K15: 0 | L15: 0 | M15: 0 | N15: 0 | O15: 0 | Q15: -2921738.5 | R15: -2944787.4 | S15: 23048.93 | T15: -0.78270268 | V15: -6890694.2 | X15: -2465161.8
A16: * COMBUSTIBLE | B16: COMBUSTIBLE | D16: -177692.04 | E16: -232201.91 | F16: -187359 | G16: -189898.4 | H16: -237922.54 | I16: 0 | J16: 0 | K16: 0 | L16: 0 | M16: 0 | N16: 0 | O16: 0 | Q16: -1025073.9 | R16: -1207787.4 | S16: 182713.54 | T16: -15.127955 | V16: -2892694.1 | X16: -1077494.6
A17: * GASTOS DE PUERTO | B17: GASTOS DE PUERTO | D17: -315779.56 | E17: -483482.65 | F17: -390235.4 | G17: -259361.56 | H17: -330840.45 | I17: 0 | J17: 0 | K17: 0 | L17: 0 | M17: 0 | N17: 0 | O17: 0 | Q17: -1779699.6 | R17: -1737000 | S17: -42699.62 | T17: 2.4582395 | V17: -3998000 | X17: -1387667.2
A18: * COSTOS DEMORAS | B18: COSTOS DE DEMORA | D18: 0 | E18: 0 | F18: 0 | G18: 0 | H18: -112500 | I18: 0 | J18: 0 | K18: 0 | L18: 0 | M18: 0 | N18: 0 | O18: 0 | Q18: -112500 | R18: 0 | S18: -112500 | T18: 0 | V18: 0 | X18: 0
B19: COMISION BROCKERAGE | D19: 0 | E19: 0 | F19: 0 | G19: 0 | H19: 0 | I19: 0 | J19: 0 | K19: 0 | L19: 0 | M19: 0 | N19: 0 | O19: 0 | Q19: 0 | R19: 0 | S19: 0 | T19: 0 | V19: 0 | X19: 0
A20: * COMISIONES VARIAS | B20: COMISIONES VARIAS | D20: 0 | E20: 0 | F20: 0 | G20: 0 | H20: 0 | I20: 0 | J20: 0 | K20: 0 | L20: 0 | M20: 0 | N20: 0 | O20: 0 | Q20: 0 | R20: 0 | S20: 0 | T20: 0 | V20: 0 | X20: 0
A21: * OTROS COSTOS DIRECTOS | B21: OTROS COSTOS DIRECTOS | D21: 0 | E21: 0 | F21: -3449.99 | G21: 0 | H21: -1015 | I21: 0 | J21: 0 | K21: 0 | L21: 0 | M21: 0 | N21: 0 | O21: 0 | Q21: -4464.99 | R21: 0 | S21: -4464.99 | T21: 0 | V21: 0 | X21: 0
B22: GASTO PUERTO POR RECIBIR | D22: 0 | E22: 0 | F22: 0 | G22: 0 | H22: 0 | I22: 0 | J22: 0 | K22: 0 | L22: 0 | M22: 0 | N22: 0 | O22: 0 | Q22: 0 | R22: 0 | S22: 0 | T22: 0 | V22: 0 | X22: 0
B24: TIME CHARTER EQUIVALENT | D24: 1228595.3 | E24: 1395507.3 | F24: 2077930.3 | G24: 1474059.6 | H24: 2020551.5 | I24: 0 | J24: 0 | K24: 0 | L24: 0 | M24: 0 | N24: 0 | O24: 0 | Q24: 8196644 | R24: 6764472.6 | S24: 1432171.4 | T24: 21.171959 | V24: 15543056 | X24: 5991339.9
A26: 638101 FLETES NAVES TERCER | B26: COSTO DE ARRIENDO NAVES | D26: 0 | E26: 0 | F26: 0 | G26: 0 | H26: -417912.29 | I26: 0 | J26: 0 | K26: 0 | L26: 0 | M26: 0 | N26: 0 | O26: 0 | Q26: -417912.29 | R26: 0 | S26: -417912.29 | T26: 0 | V26: 0 | X26: 0
B28: MARGEN BRUTO | D28: 1228595.3 | E28: 1395507.3 | F28: 2077930.3 | G28: 1474059.6 | H28: 1602639.2 | I28: 0 | J28: 0 | K28: 0 | L28: 0 | M28: 0 | N28: 0 | O28: 0 | Q28: 7778731.7 | R28: 6764472.6 | S28: 1014259.1 | T28: 14.993913 | V28: 15543056 | X28: 3336817.2
B30: GTOS. PERSONAL A BORDO | D30: -307128.8 | E30: -401979.63 | F30: -337687.38 | G30: -324665.38 | H30: -343379.91 | I30: 0 | J30: 0 | K30: 0 | L30: 0 | M30: 0 | N30: 0 | O30: 0 | Q30: -1714841.1 | R30: -1856283.8 | S30: 141442.66 | T30: -7.619668 | V30: -4344043 | X30: -1548284.2
B31: GASTOS DE PERSONAL | D31: -307128.8 | E31: -401979.63 | F31: -337687.38 | G31: -324665.38 | H31: -343379.91 | I31: 0 | J31: 0 | K31: 0 | L31: 0 | M31: 0 | N31: 0 | O31: 0 | Q31: -1714841.1 | R31: -1856283.8 | S31: 141442.66 | T31: -7.619668 | V31: -4344043 | X31: -1548284.2
T32: 0
A33: * SUELDOS | B33: SUELDOS | D33: -185547.12 | E33: -279897.96 | F33: -193455.21 | G33: -203027.9 | H33: -209116.51 | I33: 0 | J33: 0 | K33: 0 | L33: 0 | M33: 0 | N33: 0 | O33: 0 | Q33: -1071044.7 | R33: -1046041.4 | S33: -25003.26 | T33: 2.3902743 | V33: -2411431.3 | X33: -982081.21
A34: * VACACIONES | B34: VACACIONES | D34: -12772.42 | E34: -13543.83 | F34: -12200.26 | G34: -12032.7 | H34: -19470.34 | I34: 0 | J34: 0 | K34: 0 | L34: 0 | M34: 0 | N34: 0 | O34: 0 | Q34: -70019.55 | R34: -80142.5 | S34: 10122.95 | T34: -12.631188 | V34: -195395.54 | X34: -45239.64
A35: * GRATIFICACIONES | B35: GRATIFICACIONES | D35: -19794.73 | E35: -22656.3 | F35: -32887.92 | G35: -28723.68 | H35: -36745.98 | I35: 0 | J35: 0 | K35: 0 | L35: 0 | M35: 0 | N35: 0 | O35: 0 | Q35: -140808.61 | R35: -212141.82 | S35: 71333.21 | T35: -33.625247 | V35: -487906.62 | X35: -116457.09
A36: * BENEFICIOS SOCIALES | B36: BENEFICIOS SOCIALES | D36: -22418.72 | E36: -15939.07 | F36: -18340.52 | G36: -802.07 | H36: -14930.08 | I36: 0 | J36: 0 | K36: 0 | L36: 0 | M36: 0 | N36: 0 | O36: 0 | Q36: -72430.46 | R36: -91666.2 | S36: 19235.74 | T36: -20.98455 | V36: -223491.6 | X36: -64643.3
A37: * ESSALUD | B37: ESSALUD | D37: -12214.01 | E37: -17548.28 | F37: -11487.45 | G37: -11360.94 | H37: -12646.21 | I37: 0 | J37: 0 | K37: 0 | L37: 0 | M37: 0 | N37: 0 | O37: 0 | Q37: -65256.89 | R37: -71318.9 | S37: 6062.01 | T37: -8.4998647 | V37: -173882.9 | X37: -56582.01
A38: * E.P.S. /GASTOS MEDICOS | B38: E.P.S. /GASTOS MEDICOS | D38: -7964.11 | E38: -9812.63 | F38: -6099.32 | G38: -895.91 | H38: -11480.44 | I38: 0 | J38: 0 | K38: 0 | L38: 0 | M38: 0 | N38: 0 | O38: 0 | Q38: -36252.41 | R38: -36000 | S38: -252.41 | T38: 0.70113889 | V38: -86400 | X38: -40647.63
A39: * VESTUARIO | B39: VESTUARIO | D39: -7854.87 | E39: -8.7 | F39: 0 | G39: -415.46 | H39: -156.38 | I39: 0 | J39: 0 | K39: 0 | L39: 0 | M39: 0 | N39: 0 | O39: 0 | Q39: -8435.41 | R39: -8500 | S39: 64.59 | T39: -0.75988235 | V39: -20400 | X39: -5359.92
A40: * CAPACITACION | B40: CAPACITACION | D40: -185.37 | E40: -335.49 | F40: -47.72 | G40: -754.84 | H40: -859.98 | I40: 0 | J40: 0 | K40: 0 | L40: 0 | M40: 0 | N40: 0 | O40: 0 | Q40: -2183.4 | R40: -8000 | S40: 5816.6 | T40: -72.7075 | V40: -19200 | X40: -2213.04
A41: * TRASLADO DE TRIPULACION | B41: TRASLADO DE TRIPULACION | D41: -14053.24 | E41: -18198.72 | F41: -13049.19 | G41: -19878.66 | H41: -13985.06 | I41: 0 | J41: 0 | K41: 0 | L41: 0 | M41: 0 | N41: 0 | O41: 0 | Q41: -79164.87 | R41: -72000 | S41: -7164.87 | T41: 9.9512083 | V41: -172800 | X41: -49183.5
A42: * OTROS GTOS. DE PERSONAL | B42: OTROS GTOS. DE PERSONAL | D42: -24369.17 | E42: -24024.36 | F42: -23445.91 | G42: -23774.74 | H42: -23986.35 | I42: 0 | J42: 0 | K42: 0 | L42: 0 | M42: 0 | N42: 0 | O42: 0 | Q42: -119600.53 | R42: -131033.6 | S42: 11433.07 | T42: -8.7252964 | V42: -314480.64 | X42: -117930.19
A43: * VIVERES DE TRIPULACION | B43: VIVERES DE TRIPULACION | D43: 44.96 | E43: -14.29 | F43: -26673.88 | G43: -22998.48 | H43: -2.58 | I43: 0 | J43: 0 | K43: 0 | L43: 0 | M43: 0 | N43: 0 | O43: 0 | Q43: -49644.27 | R43: -99439.3 | S43: 49795.03 | T43: -50.075805 | V43: -238654.32 | X43: -67946.71
B45: GASTOS DE LA NAVE | D45: -117932.96 | E45: -220527.16 | F45: -172453.84 | G45: -251079.25 | H45: -229408.29 | I45: 0 | J45: 0 | K45: 0 | L45: 0 | M45: 0 | N45: 0 | O45: 0 | Q45: -991401.5 | R45: -769690 | S45: -221711.5 | T45: 28.805298 | V45: -1828384 | X45: -881805.23
A46: * LUBRICANTES | B46: LUBRICANTES | D46: -27161.45 | E46: -53104.49 | F46: -5587.31 | G46: -4539.43 | H46: -36685.46 | I46: 0 | J46: 0 | K46: 0 | L46: 0 | M46: 0 | N46: 0 | O46: 0 | Q46: -127078.14 | R46: -81880 | S46: -45198.14 | T46: 55.200464 | V46: -235840 | X46: -64100.86
A47: * REPUESTOS Y MANTENIMIEN | B47: REPUESTOS Y MANTENIMIENTO | D47: -18503.14 | E47: -95346.84 | F47: -106898.64 | G47: -118927.73 | H47: -92465 | I47: 0 | J47: 0 | K47: 0 | L47: 0 | M47: 0 | N47: 0 | O47: 0 | Q47: -432141.35 | R47: -349350 | S47: -82791.35 | T47: 23.698683 | V47: -783600 | X47: -423284.52
A48: * MATERIAL CONSUMIBLE | B48: MATERIAL CONSUMIBLE | D48: -39873.04 | E48: -13267.93 | F48: -23365.59 | G48: -60533.11 | H48: -46452.08 | I48: 0 | J48: 0 | K48: 0 | L48: 0 | M48: 0 | N48: 0 | O48: 0 | Q48: -183491.75 | R48: -129000 | S48: -54491.75 | T48: 42.241667 | V48: -309600 | X48: -159038.21
...

Sheet PETRAL GRR3
B2: US$ Dolar | C2: Enero | D2: Febrero | E2: Marzo | F2: Abril | G2: Mayo | H2: Junio | I2: Julio | J2: Agosto | K2: Setiembre | L2: Octubre | M2: Noviembre | N2: Diciembre | O2: Acum. 2026 | P2: Ppto.Acum a 3 | Q2: Variacion | R2: Ppto Anual | S2: % | T2: Ppto Mens | U2: Real A o anterior
B3: ** VENTAS | C3: -1722066.9 | D3: -2111191.9 | E3: -2658974.7 | F3: 0 | G3: 0 | H3: 0 | I3: 0 | J3: 0 | K3: 0 | L3: 0 | M3: 0 | N3: 0 | O3: -6492233.4 | P3: -5898825 | Q3: 593408.44 | R3: -22433750 | S3: -10.0598 | T3: -1997375 | U3: 0
B4: 704121 FLETES A TERC-NAV P | C4: 0 | D4: 0 | E4: 0 | F4: 0 | G4: 0 | H4: 0 | I4: 0 | J4: 0 | K4: 0 | L4: 0 | M4: 0 | N4: 0 | O4: 0 | P4: -4677825 | Q4: -4677825 | R4: -18193750 | S4: 100 | T4: -1594375 | U4: 0
B5: 703213 FLETES A T-NAV PR L | C5: -1041229.4 | D5: -1827318.9 | E5: -1992698.2 | F5: 0 | G5: 0 | H5: 0 | I5: 0 | J5: 0 | K5: 0 | L5: 0 | M5: 0 | N5: 0 | O5: -4861246.6 | P5: 0 | Q5: 4861246.6 | R5: 0 | S5: 0 | T5: 0 | U5: 0
B6: * HIRE | C6: -1041229.4 | D6: -1827318.9 | E6: -1992698.2 | F6: 0 | G6: 0 | H6: 0 | I6: 0 | J6: 0 | K6: 0 | L6: 0 | M6: 0 | N6: 0 | O6: -4861246.6 | P6: -4677825 | Q6: 183421.56 | R6: -18193750 | S6: -3.9211 | T6: -1594375 | U6: 0
B7: 704123 DEMORAS | C7: 0 | D7: 0 | E7: 0 | F7: 0 | G7: 0 | H7: 0 | I7: 0 | J7: 0 | K7: 0 | L7: 0 | M7: 0 | N7: 0 | O7: 0 | P7: -980000 | Q7: -980000 | R7: -3460000 | S7: 100 | T7: -340000 | U7: 0
B8: 703115 DEMORAS EXPORTACION | C8: 87307.99 | D8: 311956.22 | E8: -405189.18 | F8: 0 | G8: 0 | H8: 0 | I8: 0 | J8: 0 | K8: 0 | L8: 0 | M8: 0 | N8: 0 | O8: -5924.97 | P8: 0 | Q8: 5924.97 | R8: 0 | S8: 0 | T8: 0 | U8: 0
B9: 703215 DEMORAS -LOCAL | C9: -691997.24 | D9: -527306.22 | E9: -157347.83 | F9: 0 | G9: 0 | H9: 0 | I9: 0 | J9: 0 | K9: 0 | L9: 0 | M9: 0 | N9: 0 | O9: -1376651.3 | P9: 0 | Q9: 1376651.3 | R9: 0 | S9: 0 | T9: 0 | U9: 0
B10: * DEMORAS | C10: -604689.25 | D10: -215350 | E10: -562537.01 | F10: 0 | G10: 0 | H10: 0 | I10: 0 | J10: 0 | K10: 0 | L10: 0 | M10: 0 | N10: 0 | O10: -1382576.3 | P10: -980000 | Q10: 402576.26 | R10: -3460000 | S10: -41.0792 | T10: -340000 | U10: 0
B11: 704136 SERV DE ATENC EN PU | C11: 0 | D11: 0 | E11: 0 | F11: 0 | G11: 0 | H11: 0 | I11: 0 | J11: 0 | K11: 0 | L11: 0 | M11: 0 | N11: 0 | O11: 0 | P11: -241000 | Q11: -241000 | R11: -780000 | S11: 100 | T11: -63000 | U11: 0
B12: 703118 SERV ATENC EN PUE E | C12: -295.62 | D12: 14295.62 | E12: 6000 | F12: 0 | G12: 0 | H12: 0 | I12: 0 | J12: 0 | K12: 0 | L12: 0 | M12: 0 | N12: 0 | O12: 20000 | P12: 0 | Q12: -20000 | R12: 0 | S12: 0 | T12: 0 | U12: 0
B13: 703218 SERV ATENC EN PUE L | C13: -75852.59 | D13: -82818.52 | E13: -109739.51 | F13: 0 | G13: 0 | H13: 0 | I13: 0 | J13: 0 | K13: 0 | L13: 0 | M13: 0 | N13: 0 | O13: -268410.62 | P13: 0 | Q13: 268410.62 | R13: 0 | S13: 0 | T13: 0 | U13: 0
B14: * INGRESOS DE PUERTO | C14: -76148.21 | D14: -68522.9 | E14: -103739.51 | F14: 0 | G14: 0 | H14: 0 | I14: 0 | J14: 0 | K14: 0 | L14: 0 | M14: 0 | N14: 0 | O14: -248410.62 | P14: -241000 | Q14: 7410.62 | R14: -780000 | S14: -3.0749 | T14: -63000 | U14: 0
... B222: ******* EBITDA | C222: -663120.57 | D222: -616129.81 | E222: -1425397.6 | F222: 0 | G222: 0 | H222: 0 | I222: 0 | J222: 0 | K222: 0 | L222: 0 | M222: 0 | N222: 0 | O222: -2704648 | P222: -2166328.5 | Q222: 538319.53 | R222: -7990408.8 | S222: -24.8494 | T222: -769572.46 | U222: 0

Sheet Hoja1
B2: US$ Dolar | C2: Enero | D2: Febrero | E2: Marzo | F2: Abril | G2: Mayo | H2: Junio | I2: Julio | J2: Agosto | K2: Setiembre | L2: Octubre | M2: Noviembre | N2: Diciembre | O2: Acum. 2025 | P2: Ppto.Acum a 11 | Q2: Variacion | R2: Ppto Anual | S2: % | T2: Ppto Mens | U2: Real A o anterior
B3: *** VENTAS | C3: 0 | D3: 0 | E3: 0 | F3: 0 | G3: 0 | H3: 0 | I3: 0 | J3: 0 | K3: 0 | L3: -17278289 | M3: -1529551.4 | N3: 0 | O3: -18807841 | P3: -18366587 | Q3: 441253.29 | R3: -19976053 | S3: -2.4025 | T3: -1849240.7 | U3: 0
B4: 704121 FLETES A TERC-NAV | C4: 0 | D4: 0 | E4: 0 | F4: 0 | G4: 0 | H4: 0 | I4: 0 | J4: 0 | K4: 0 | L4: 0 | M4: 0 | N4: 0 | O4: 0 | P4: -14954265 | Q4: -14954265 | R4: -16266065 | S4: 100 | T4: -1521575 | U4: 0
B5: 703213 FLETES A T-NAV PR | C5: 0 | D5: 0 | E5: 0 | F5: 0 | G5: 0 | H5: 0 | I5: 0 | J5: 0 | K5: 0 | L5: -12453731 | M5: -1110701.1 | N5: 0 | O5: -13564433 | P5: 0 | Q5: 13564433 | R5: 0 | S5: 0 | T5: 0 | U5: 0
B6: * HIRE | C6: 0 | D6: 0 | E6: 0 | F6: 0 | G6: 0 | H6: 0 | I6: 0 | J6: 0 | K6: 0 | L6: -12453731 | M6: -1110701.1 | N6: 0 | O6: -13564433 | P6: -14954265 | Q6: -1389832.4 | R6: -16266065 | S6: 9.2939 | T6: -1521575 | U6: 0
B7: 704123 DEMORAS | C7: 0 | D7: 0 | E7: 0 | F7: 0 | G7: 0 | H7: 0 | I7: 0 | J7: 0 | K7: 0 | L7: 0 | M7: 0 | N7: 0 | O7: 0 | P7: -2768322.3 | Q7: -2768322.3 | R7: -3019987.9 | S7: 100 | T7: -251665.66 | U7: 0
B8: 703115 DEMORAS EXPORTACIO | C8: 0 | D8: 0 | E8: 0 | F8: 0 | G8: 0 | H8: 0 | I8: 0 | J8: 0 | K8: 0 | L8: -165339.11 | M8: 199540.87 | N8: 0 | O8: 34201.76 | P8: 0 | Q8: -34201.76 | R8: 0 | S8: 0 | T8: 0 | U8: 0
B9: 703215 DEMORAS -LOCAL | C9: 0 | D9: 0 | E9: 0 | F9: 0 | G9: 0 | H9: 0 | I9: 0 | J9: 0 | K9: 0 | L9: -4150714 | M9: -558872.76 | N9: 0 | O9: -4709586.8 | P9: 0 | Q9: 4709586.8 | R9: 0 | S9: 0 | T9: 0 | U9: 0
B10: * DEMORAS | C10: 0 | D10: 0 | E10: 0 | F10: 0 | G10: 0 | H10: 0 | I10: 0 | J10: 0 | K10: 0 | L10: -4316053.1 | M10: -359331.89 | N10: 0 | O10: -4675385 | P10: -2768322.3 | Q10: 1907062.7 | R10: -3019987.9 | S10: -68.8888 | T10: -251665.66 | U10: 0
B11: 704136 SERV DE ATENC EN P | C11: 0 | D11: 0 | E11: 0 | F11: 0 | G11: 0 | H11: 0 | I11: 0 | J11: 0 | K11: 0 | L11: 0 | M11: 0 | N11: 0 | O11: 0 | P11: -644000 | Q11: -644000 | R11: -690000 | S11: 100 | T11: -76000 | U11: 0
B12: 703118 SERV ATENC EN PUE | C12: 0 | D12: 0 | E12: 0 | F12: 0 | G12: 0 | H12: 0 | I12: 0 | J12: 0 | K12: 0 | L12: 19018 | M12: 29096 | N12: 0 | O12: 48114 | P12: 0 | Q12: -48114 | R12: 0 | S12: 0 | T12: 0 | U12: 0
B13: 703218 SERV ATENC EN PUE | C13: 0 | D13: 0 | E13: 0 | F13: 0 | G13: 0 | H13: 0 | I13: 0 | J13: 0 | K13: 0 | L13: -527522.55 | M13: -88614.44 | N13: 0 | O13: -616136.99 | P13: 0 | Q13: 616136.99 | R13: 0 | S13: 0 | T13: 0 | U13: 0
B14: * INGRESOS DE PUERTO | C14: 0 | D14: 0 | E14: 0 | F14: 0 | G14: 0 | H14: 0 | I14: 0 | J14: 0 | K14: 0 | L14: -508504.55 | M14: -59518.44 | N14: 0 | O14: -568022.99 | P14: -644000 | Q14: -75977.01 | R14: -690000 | S14: 11.7977 | T14: -76000 | U14: 0
... B240: ******** EBITDA | C240: 0 | D240: 0 | E240: 0 | F240: 0 | G240: 0 | H240: 0 | I240: 0 | J240: 0 | K240: 0 | L240: -6681820 | M240: -500897.96 | N240: 0 | O240: -7182718 | P240: -6704365 | Q240: 478352.9 | R240: -7251419.3 | S240: -7.1349 | T240: -788830.47 | U240: 0

Sheet Moquegua
Z1: =+PETRAL!Z1 -> 5
B2: Control Presupuestal
B3: =+PETRAL!B3 -> 46143 | D3: MOQUEGUA
Q5: REAL | R5: PRESUP. | V5: PPTO. | X5: Real Acum.
B6: (US$ Dólares) | D6: ENE | E6: FEB | F6: MAR | G6: ABR | H6: MAY | I6: JUN | J6: JUL | K6: AGO | L6: SET | M6: OCT | N6: NOV | O6: DIC | Q6: ACUMUL. | R6: ACUMUL. | S6: VARIACION | T6: % | V6: ANUAL | X6: =+PETRAL!X6 -> 45778
B8: VENTAS | D8: 551026.33 | E8: 1155413 | F8: 1436461.6 | G8: 865657.45 | H8: 1314549.9 | I8: 0 | J8: 0 | K8: 0 | L8: 0 | M8: 0 | N8: 0 | O8: 0 | Q8: 5323108.3 | R8: 4461285 | S8: 861823.31 | T8: 19.317827 | V8: 11408070 | X8: 3443429.9
A9: * HIRE | B9: HIRE | D9: 197159.69 | E9: 1018421.9 | F9: 1132813.4 | G9: 547915.66 | H9: 1220211.7 | I9: 0 | J9: 0 | K9: 0 | L9: 0 | M9: 0 | N9: 0 | O9: 0 | Q9: 4116522.4 | R9: 3684285 | S9: 432237.39 | T9: 11.731921 | V9: 9558070 | X9: 2472155.7
B10: VENTA DE TERCEROS | D10: 0 | E10: 0 | F10: 0 | G10: 0 | H10: 0 | I10: 0 | J10: 0 | K10: 0 | L10: 0 | M10: 0 | N10: 0 | O10: 0 | Q10: 0 | R10: 0 | S10: 0 | T10: 0 | V10: 0 | X10: 0
A11: * DEMORAS | B11: DEMORAS | D11: 331565.33 | E11: 130225.35 | F11: 226211.46 | G11: 296523.81 | H11: 61681.01 | I11: 0 | J11: 0 | K11: 0 | L11: 0 | M11: 0 | N11: 0 | O11: 0 | Q11: 1046207 | R11: 710000 | S11: 336206.96 | T11: 47.353093 | V11: 1710000 | X11: 873246.01
A12: * INGRESOS DE PUERTO | B12: INGRESOS DE PUERTO | D12: 22301.31 | E12: 6765.71 | F12: 77436.73 | G12: 21217.98 | H12: 32657.23 | I12: 0 | J12: 0 | K12: 0 | L12: 0 | M12: 0 | N12: 0 | O12: 0 | Q12: 160378.96 | R12: 67000 | S12: 93378.96 | T12: 139.37158 | V12: 140000 | X12: 98028.16
A13: * OTROS INGRESOS | B13: OTROS INGRESOS | D13: 0 | E13: 0 | F13: 0 | G13: 0 | H13: 0 | I13: 0 | J13: 0 | K13: 0 | L13: 0 | M13: 0 | N13: 0 | O13: 0 | Q13: 0 | R13: 0 | S13: 0 | T13: 0 | V13: 0 | X13: 0
B15: COSTOS DIRECTOS | D15: -113464.26 | E15: -270359.16 | F15: -447348.26 | G15: -144973.84 | H15: -318588.34 | I15: 0 | J15: 0 | K15: 0 | L15: 0 | M15: 0 | N15: 0 | O15: 0 | Q15: -1294733.9 | R15: -1142642.6 | S15: -152091.28 | T15: 13.310486 | V15: -2977950.8 | X15: -886349.17
A16: * COMBUSTIBLE | B16: COMBUSTIBLE | D16: -58113.65 | E16: -104266.83 | F16: -109571.24 | G16: -82631.52 | H16: -99174.25 | I16: 0 | J16: 0 | K16: 0 | L16: 0 | M16: 0 | N16: 0 | O16: 0 | Q16: -453757.49 | R16: -410642.58 | S16: -43114.91 | T16: 10.499376 | V16: -1123950.8 | X16: -377896.13
A17: * GASTOS DE PUERTO | B17: GASTOS DE PUERTO | D17: -55350.61 | E17: -166092.33 | F17: -337777.02 | G17: -62342.32 | H17: -219414.09 | I17: 0 | J17: 0 | K17: 0 | L17: 0 | M17: 0 | N17: 0 | O17: 0 | Q17: -840976.37 | R17: -732000 | S17: -108976.37 | T17: 14.887482 | V17: -1854000 | X17: -508453.04
B18: COSTOS DE DEMORA | D18: 0 | E18: 0 | F18: 0 | G18: 0 | H18: 0 | I18: 0 | J18: 0 | K18: 0 | L18: 0 | M18: 0 | N18: 0 | O18: 0 | Q18: 0 | R18: 0 | S18: 0 | T18: 0 | V18: 0 | X18: 0
B19: COMISION BROCKERAGE | D19: 0 | E19: 0 | F19: 0 | G19: 0 | H19: 0 | I19: 0 | J19: 0 | K19: 0 | L19: 0 | M19: 0 | N19: 0 | O19: 0 | Q19: 0 | R19: 0 | S19: 0 | T19: 0 | V19: 0 | X19: 0
A20: * COMISIONES VARIAS | B20: COMISIONES VARIAS | D20: 0 | E20: 0 | F20: 0 | G20: 0 | H20: 0 | I20: 0 | J20: 0 | K20: 0 | L20: 0 | M20: 0 | N20: 0 | O20: 0 | Q20: 0 | R20: 0 | S20: 0 | T20: 0 | V20: 0 | X20: 0
A21: * OTROS COSTOS DIRECTOS | B21: OTROS COSTOS DIRECTOS | D21: 0 | E21: 0 | F21: 0 | G21: 0 | H21: 0 | I21: 0 | J21: 0 | K21: 0 | L21: 0 | M21: 0 | N21: 0 | O21: 0 | Q21: 0 | R21: 0 | S21: 0 | T21: 0 | V21: 0 | X21: 0
B22: GASTO PUERTO POR RECIBIR | D22: 0 | E22: 0 | F22: 0 | G22: 0 | H22: 0 | I22: 0 | J22: 0 | K22: 0 | L22: 0 | M22: 0 | N22: 0 | O22: 0 | Q22: 0 | R22: 0 | S22: 0 | T22: 0 | V22: 0 | X22: 0
B24: TIME CHARTER EQUIVALENT | D24: 437562.07 | E24: 885053.82 | F24: 989113.38 | G24: 720683.61 | H24: 995961.57 | I24: 0 | J24: 0 | K24: 0 | L24: 0 | M24: 0 | N24: 0 | O24: 0 | Q24: 4028374.4 | R24: 3318642.4 | S24: 709732.03 | T24: 21.386216 | V24: 8430119.2 | X24: 2557080.7
B26: COSTO DE ARRIENDO NAVES | D26: 0 | E26: 0 | F26: 0 | G26: 0 | H26: 0 | I26: 0 | J26: 0 | K26: 0 | L26: 0 | M26: 0 | N26: 0 | O26: 0 | Q26: 0 | R26: 0 | S26: 0 | T26: 0 | V26: 0 | X26: 0
B28: MARGEN BRUTO | D28: 437562.07 | E28: 885053.82 | F28: 989113.38 | G28: 720683.61 | H28: 995961.57 | I28: 0 | J28: 0 | K28: 0 | L28: 0 | M28: 0 | N28: 0 | O28: 0 | Q28: 4028374.4 | R28: 3318642.4 | S28: 709732.03 | T28: 21.386216 | V28: 8430119.2 | X28: 2557080.7
B30: GTOS. PERSONAL A BORDO | D30: -140045.31 | E30: -202734.27 | F30: -168711.03 | G30: -163794.23 | H30: -178734.37 | I30: 0 | J30: 0 | K30: 0 | L30: 0 | M30: 0 | N30: 0 | O30: 0 | Q30: -854019.21 | R30: -928141.88 | S30: 74122.67 | T30: -7.9861357 | V30: -2172021.5 | X30: -767899.81
B31: GASTOS DE PERSONAL | D31: -140045.31 | E31: -202734.27 | F31: -168711.03 | G31: -163794.23 | H31: -178734.37 | I31: 0 | J31: 0 | K31: 0 | L31: 0 | M31: 0 | N31: 0 | O31: 0 | Q31: -854019.21 | R31: -928141.88 | S31: 74122.67 | T31: -7.9861357 | V31: -2172021.5 | X31: -767899.81
A33: * SUELDOS | B33: SUELDOS | D33: -79110.27 | E33: -133896.9 | F33: -99027.32 | G33: -103985.94 | H33: -114436.43 | I33: 0 | J33: 0 | K33: 0 | L33: 0 | M33: 0 | N33: 0 | O33: 0 | Q33: -530456.86 | R33: -523020.72 | S33: -7436.14 | T33: 1.4217678 | V33: -1205715.7 | X33: -507276.36
A34: * VACACIONES | B34: VACACIONES | D34: -6825.94 | E34: -8346.57 | F34: -4085.82 | G34: -8127.8 | H34: -8509.89 | I34: 0 | J34: 0 | K34: 0 | L34: 0 | M34: 0 | N34: 0 | O34: 0 | Q34: -35896.02 | R34: -40071.25 | S34: 4175.23 | T34: -10.419515 | V34: -97697.77 | X34: -22304.81
A35: * GRATIFICACIONES | B35: GRATIFICACIONES | D35: -10356.88 | E35: -11849.02 | F35: -14640.11 | G35: -15733.28 | H35: -17093.28 | I35: 0 | J35: 0 | K35: 0 | L35: 0 | M35: 0 | N35: 0 | O35: 0 | Q35: -69672.57 | R35: -106070.91 | S35: 36398.34 | T35: -34.315101 | V35: -243953.31 | X35: -53578.04
A36: * BENEFICIOS SOCIALES | B36: BENEFICIOS SOCIALES | D36: -11520.37 | E36: -8410.7 | F36: -7077.03 | G36: -4051.38 | H36: -7148.94 | I36: 0 | J36: 0 | K36: 0 | L36: 0 | M36: 0 | N36: 0 | O36: 0 | Q36: -38208.42 | R36: -45833.1 | S36: 7624.68 | T36: -16.63575 | V36: -111745.8 | X36: -31952.9
A37: * ESSALUD | B37: ESSALUD | D37: -6369.62 | E37: -9129.82 | F37: -5583.53 | G37: -6030.76 | H37: -6852.64 | I37: 0 | J37: 0 | K37: 0 | L37: 0 | M37: 0 | N37: 0 | O37: 0 | Q37: -33966.37 | R37: -35659.45 | S37: 1693.08 | T37: -4.7479139 | V37: -86941.45 | X37: -26122.15
A38: * E.P.S. /GASTOS MEDICOS | B38: E.P.S. /GASTOS MEDICOS | D38: -4023.82 | E38: -5056.51 | F38: -3173.09 | G38: -516.69 | H38: -6128.46 | I38: 0 | J38: 0 | K38: 0 | L38: 0 | M38: 0 | N38: 0 | O38: 0 | Q38: -18898.57 | R38: -18000 | S38: -898.57 | T38: 4.9920556 | V38: -43200 | X38: -19870.67
A39: * VESTUARIO | B39: VESTUARIO | D39: -2419.44 | E39: 0 | F39: 0 | G39: -402.71 | H39: -156.38 | I39: 0 | J39: 0 | K39: 0 | L39: 0 | M39: 0 | N39: 0 | O39: 0 | Q39: -2978.53 | R39: -4250 | S39: 1271.47 | T39: -29.916941 | V39: -10200 | X39: -2746.29
A40: * CAPACITACION | B40: CAPACITACION | D40: -156.44 | E40: -295.35 | F40: -47.72 | G40: -555.83 | H40: -281.72 | I40: 0 | J40: 0 | K40: 0 | L40: 0 | M40: 0 | N40: 0 | O40: 0 | Q40: -1337.06 | R40: -4000 | S40: 2662.94 | T40: -66.5735 | V40: -9600 | X40: -739.16
A41: * TRASLADO DE TRIPULACION | B41: TRASLADO DE TRIPULACION | D41: -7072.59 | E41: -13714 | F41: -4612.19 | G41: -12497.59 | H41: -6070.33 | I41: 0 | J41: 0 | K41: 0 | L41: 0 | M41: 0 | N41: 0 | O41: 0 | Q41: -43966.7 | R41: -36000 | S41: -7966.7 | T41: 22.129722 | V41: -86400 | X41: -14256.23
A42: * OTROS GTOS. DE PERSONAL | B42: OTROS GTOS. DE PERSONAL | D42: -12215.63 | E42: -12035.4 | F42: -11745.88 | G42: -11887.18 | H42: -12004.45 | I42: 0 | J42: 0 | K42: 0 | L42: 0 | M42: 0 | N42: 0 | O42: 0 | Q42: -59888.54 | R42: -65516.8 | S42: 5628.26 | T42: -8.59056 | V42: -157240.32 | X42: -59147.39
A43: * VIVERES DE TRIPULACION | B43: VIVERES DE TRIPULACION | D43: 25.69 | E43: 0 | F43: -18718.34 | G43: -5.07 | H43: -51.85 | I43: 0 | J43: 0 | K43: 0 | L43: 0 | M43: 0 | N43: 0 | O43: 0 | Q43: -18749.57 | R43: -49719.65 | S43: 30970.08 | T43: -62.289417 | V43: -119327.16 | X43: -29905.81
B45: GASTOS DE LA NAVE | D45: -44172.86 | E45: -88911.86 | F45: -75689.03 | G45: -158573.23 | H45: -132015.16 | I45: 0 | J45: 0 | K45: 0 | L45: 0 | M45: 0 | N45: 0 | O45: 0 | Q45: -499362.14 | R45: -369020 | S45: -130342.14 | T45: 35.321159 | V45: -916492 | W45: 0 | X45: -511345.58
A46: * LUBRICANTES | B46: LUBRICANTES | D46: -8861.45 | E46: -25087.68 | F46: -5586 | G46: -7.86 | H46: -12192.14 | I46: 0 | J46: 0 | K46: 0 | L46: 0 | M46: 0 | N46: 0 | O46: 0 | Q46: -51735.13 | R46: -40940 | S46: -10795.13 | T46: 26.368173 | V46: -116020 | X46: -19931.04
A47: * REPUESTOS Y MANTENIMIEN | B47: REPUESTOS Y MANTENIMIENTO | D47: -8167.26 | E47: -19649.35 | F47: -44576.58 | G47: -82427.27 | H47: -72038.39 | I47: 0 | J47: 0 | K47: 0 | L47: 0 | M47: 0 | N47: 0 | O47: 0 | Q47: -226858.85 | R47: -160350 | S47: -66508.85 | T47: 41.4773 | V47: -399600 | X47: -304164.95
A48: * MATERIAL CONSUMIBLE | B48: MATERIAL CONSUMIBLE | D48: -10263.24 | E48: -8892.01 | F48: -5841.37 | G48: -38130.09 | H48: -22994.97 | I48: 0 | J48: 0 | K48: 0 | L48: 0 | M48: 0 | N48: 0 | O48: 0 | Q48: -86121.68 | R48: -63000 | S48: -23121.68 | T48: 36.701079 | V48: -151200 | X48: -70471.33
A49: * CERTIF. /INSPECCION | B49: CERTIF. /INSPECCION | D49: -4031.75 | E49: -16839.8 | F49: -2077.21 | G49: -19266.19 | H49: -4878.42 | I49: 0 | J49: 0 | K49: 0 | L49: 0 | M49: 0 | N49: 0 | O49: 0 | Q49: -47093.37 | R49: -20450 | S49: -26643.37 | T49: 130.28543 | V49: -47400 | X49: -33893.45
...

Sheet MOQUEGUA GRR3
B2: US$ Dolar | C2: Enero | D2: Febrero | E2: Marzo | F2: Abril | G2: Mayo | H2: Junio | I2: Julio | J2: Agosto | K2: Setiembre | L2: Octubre | M2: Noviembre | N2: Diciembre | O2: Acum. 2026 | P2: Ppto.Acum a 3 | Q2: Variacion | R2: Ppto Anual | S2: % | T2: Ppto Mens | U2: Real A o anterior
B3: ** VENTAS | C3: -551026.33 | D3: -1155413 | E3: -1436461.6 | F3: 0 | G3: 0 | H3: 0 | I3: 0 | J3: 0 | K3: 0 | L3: 0 | M3: 0 | N3: 0 | O3: -3142901 | P3: -2750040 | Q3: 392860.95 | R3: -11408070 | S3: -14.2856 | T3: -947780 | U3: 0
B4: 704121 FLETES A TERC-NAV P | C4: 0 | D4: 0 | E4: 0 | F4: 0 | G4: 0 | H4: 0 | I4: 0 | J4: 0 | K4: 0 | L4: 0 | M4: 0 | N4: 0 | O4: 0 | P4: -2249040 | Q4: -2249040 | R4: -9558070 | S4: 100 | T4: -784780 | U4: 0
B5: 703213 FLETES A T-NAV PR L | C5: -197159.69 | D5: -1018421.9 | E5: -1132813.4 | F5: 0 | G5: 0 | H5: 0 | I5: 0 | J5: 0 | K5: 0 | L5: 0 | M5: 0 | N5: 0 | O5: -2348395.1 | P5: 0 | Q5: 2348395.1 | R5: 0 | S5: 0 | T5: 0 | U5: 0
B6: * HIRE | C6: -197159.69 | D6: -1018421.9 | E6: -1132813.4 | F6: 0 | G6: 0 | H6: 0 | I6: 0 | J6: 0 | K6: 0 | L6: 0 | M6: 0 | N6: 0 | O6: -2348395.1 | P6: -2249040 | Q6: 99355.06 | R6: -9558070 | S6: -4.4177 | T6: -784780 | U6: 0
B7: 704123 DEMORAS | C7: 0 | D7: 0 | E7: 0 | F7: 0 | G7: 0 | H7: 0 | I7: 0 | J7: 0 | K7: 0 | L7: 0 | M7: 0 | N7: 0 | O7: 0 | P7: -440000 | Q7: -440000 | R7: -1710000 | S7: 100 | T7: -160000 | U7: 0
B8: 703115 DEMORAS EXPORTACION | C8: -153291.04 | D8: 297956.27 | E8: -200973.33 | F8: 0 | G8: 0 | H8: 0 | I8: 0 | J8: 0 | K8: 0 | L8: 0 | M8: 0 | N8: 0 | O8: -56308.1 | P8: 0 | Q8: 56308.1 | R8: 0 | S8: 0 | T8: 0 | U8: 0
B9: 703215 DEMORAS -LOCAL | C9: -178274.29 | D9: -428181.62 | E9: -25238.13 | F9: 0 | G9: 0 | H9: 0 | I9: 0 | J9: 0 | K9: 0 | L9: 0 | M9: 0 | N9: 0 | O9: -631694.04 | P9: 0 | Q9: 631694.04 | R9: 0 | S9: 0 | T9: 0 | U9: 0
B10: * DEMORAS | C10: -331565.33 | D10: -130225.35 | E10: -226211.46 | F10: 0 | G10: 0 | H10: 0 | I10: 0 | J10: 0 | K10: 0 | L10: 0 | M10: 0 | N10: 0 | O10: -688002.14 | P10: -440000 | Q10: 248002.14 | R10: -1710000 | S10: -56.3641 | T10: -160000 | U10: 0
B11: 704136 SERV DE ATENC EN PU | C11: 0 | D11: 0 | E11: 0 | F11: 0 | G11: 0 | H11: 0 | I11: 0 | J11: 0 | K11: 0 | L11: 0 | M11: 0 | N11: 0 | O11: 0 | P11: -61000 | Q11: -61000 | R11: -140000 | S11: 100 | T11: -3000 | U11: 0
B12: 703118 SERV ATENC EN PUE E | C12: -20295.62 | D12: 20295.62 | E12: -20000 | F12: 0 | G12: 0 | H12: 0 | I12: 0 | J12: 0 | K12: 0 | L12: 0 | M12: 0 | N12: 0 | O12: -20000 | P12: 0 | Q12: 20000 | R12: 0 | S12: 0 | T12: 0 | U12: 0
B13: 703218 SERV ATENC EN PUE L | C13: -2005.69 | D13: -27061.33 | E13: -57436.73 | F13: 0 | G13: 0 | H13: 0 | I13: 0 | J13: 0 | K13: 0 | L13: 0 | M13: 0 | N13: 0 | O13: -86503.75 | P13: 0 | Q13: 86503.75 | R13: 0 | S13: 0 | T13: 0 | U13: 0
B14: * INGRESOS DE PUERTO | C14: -22301.31 | D14: -6765.71 | E14: -77436.73 | F14: 0 | G14: 0 | H14: 0 | I14: 0 | J14: 0 | K14: 0 | L14: 0 | M14: 0 | N14: 0 | O14: -106503.75 | P14: -61000 | Q14: 45503.75 | R14: -140000 | S14: -74.5963 | T14: -3000 | U14: 0
... B130: ******* EBITDA | C130: -239756.37 | D130: -581488.16 | E130: -731607.43 | F130: 0 | G130: 0 | H130: 0 | I130: 0 | J130: 0 | K130: 0 | L130: 0 | M130: 0 | N130: 0 | O130: -1552852 | P130: -1223010.1 | Q130: 329841.89 | R130: -5184547.9 | S130: -26.9697 | T130: -463425.05 | U130: 0

Sheet Hoja2
B2: US$ Dolar | C2: Enero | D2: Febrero | E2: Marzo | F2: Abril | G2: Mayo | H2: Junio | I2: Julio | J2: Agosto | K2: Setiembre | L2: Octubre | M2: Noviembre | N2: Diciembre | O2: Acum. 2025 | P2: Ppto.Acum a 11 | Q2: Variacion | R2: Ppto Anual | S2: % | T2: Ppto Mens | U2: Real A o anterior
B3: ** VENTAS | C3: 0 | D3: 0 | E3: 0 | F3: 0 | G3: 0 | H3: 0 | I3: 0 | J3: 0 | K3: 0 | L3: -8089557.2 | M3: -843919.19 | N3: 0 | O3: -8933476.4 | P3: -8835050.9 | Q3: 98425.46 | R3: -9405058.7 | S3: -1.114 | T3: -854357.81 | U3: 0
B4: 704121 FLETES A TERC-NAV P | C4: 0 | D4: 0 | E4: 0 | F4: 0 | G4: 0 | H4: 0 | I4: 0 | J4: 0 | K4: 0 | L4: 0 | M4: 0 | N4: 0 | O4: 0 | P4: -7294890 | Q4: -7294890 | R4: -7731065 | S4: 100 | T4: -707525 | U4: 0
B5: 703213 FLETES A T-NAV PR L | C5: 0 | D5: 0 | E5: 0 | F5: 0 | G5: 0 | H5: 0 | I5: 0 | J5: 0 | K5: 0 | L5: -5958195.2 | M5: -804314.52 | N5: 0 | O5: -6762509.7 | P5: 0 | Q5: 6762509.7 | R5: 0 | S5: 0 | T5: 0 | U5: 0
B6: * HIRE | C6: 0 | D6: 0 | E6: 0 | F6: 0 | G6: 0 | H6: 0 | I6: 0 | J6: 0 | K6: 0 | L6: -5958195.2 | M6: -804314.52 | N6: 0 | O6: -6762509.7 | P6: -7294890 | Q6: -532380.28 | R6: -7731065 | S6: 7.298 | T6: -707525 | U6: 0
B7: 704123 DEMORAS | C7: 0 | D7: 0 | E7: 0 | F7: 0 | G7: 0 | H7: 0 | I7: 0 | J7: 0 | K7: 0 | L7: 0 | M7: 0 | N7: 0 | O7: 0 | P7: -1439160.9 | Q7: -1439160.9 | R7: -1569993.7 | S7: 100 | T7: -130832.81 | U7: 0
B8: 703115 DEMORAS EXPORTACION | C8: 0 | D8: 0 | E8: 0 | F8: 0 | G8: 0 | H8: 0 | I8: 0 | J8: 0 | K8: 0 | L8: -43416.17 | M8: 88599.65 | N8: 0 | O8: 45183.48 | P8: 0 | Q8: -45183.48 | R8: 0 | S8: 0 | T8: 0 | U8: 0
B9: 703215 DEMORAS -LOCAL | C9: 0 | D9: 0 | E9: 0 | F9: 0 | G9: 0 | H9: 0 | I9: 0 | J9: 0 | K9: 0 | L9: -1917851.9 | M9: -107482.9 | N9: 0 | O9: -2025334.8 | P9: 0 | Q9: 2025334.8 | R9: 0 | S9: 0 | T9: 0 | U9: 0
B10: * DEMORAS | C10: 0 | D10: 0 | E10: 0 | F10: 0 | G10: 0 | H10: 0 | I10: 0 | J10: 0 | K10: 0 | L10: -1961268.1 | M10: -18883.25 | N10: 0 | O10: -1980151.3 | P10: -1439160.9 | Q10: 540990.4 | R10: -1569993.7 | S10: -37.5907 | T10: -130832.81 | U10: 0
B11: 704136 SERV DE ATENC EN PU | C11: 0 | D11: 0 | E11: 0 | F11: 0 | G11: 0 | H11: 0 | I11: 0 | J11: 0 | K11: 0 | L11: 0 | M11: 0 | N11: 0 | O11: 0 | P11: -101000 | Q11: -101000 | R11: -104000 | S11: 100 | T11: -16000 | U11: 0
B12: 703118 SERV ATENC EN PUE E | C12: 0 | D12: 0 | E12: 0 | F12: 0 | G12: 0 | H12: 0 | I12: 0 | J12: 0 | K12: 0 | L12: 11508 | M12: 39000 | N12: 0 | O12: 50508 | P12: 0 | Q12: -50508 | R12: 0 | S12: 0 | T12: 0 | U12: 0
B13: 703218 SERV ATENC EN PUE L | C13: 0 | D13: 0 | E13: 0 | F13: 0 | G13: 0 | H13: 0 | I13: 0 | J13: 0 | K13: 0 | L13: -181601.92 | M13: -59721.42 | N13: 0 | O13: -241323.34 | P13: 0 | Q13: 241323.34 | R13: 0 | S13: 0 | T13: 0 | U13: 0
B14: * INGRESOS DE PUERTO | C14: 0 | D14: 0 | E14: 0 | F14: 0 | G14: 0 | H14: 0 | I14: 0 | J14: 0 | K14: 0 | L14: -170093.92 | M14: -20721.42 | N14: 0 | O14: -190815.34 | P14: -101000 | Q14: 89815.34 | R14: -104000 | S14: -88.9261 | T14: -16000 | U14: 0
... B141: ******* EBITDA | C141: 0 | D141: 0 | E141: 0 | F141: 0 | G141: 0 | H141: 0 | I141: 0 | J141: 0 | K141: 0 | L141: -3570612.6 | M141: -377015.16 | N141: 0 | O141: -3947627.8 | P141: -3621587.1 | Q141: 326040.62 | R141: -3784174.9 | S141: -9.0027 | T141: -392021.95 | U141: 0

Sheet Tablones
Z1: =+PETRAL!Z1 -> 5
B2: Control Presupuestal
B3: =+PETRAL!B3 -> 46143 | D3: TABLONES
Q5: REAL | R5: PRESUP. | V5: PPTO. | X5: Real Acum.
B6: (US$ Dólares) | D6: ENE | E6: FEB | F6: MAR | G6: ABR | H6: MAY | I6: JUN | J6: JUL | K6: AGO | L6: SET | M6: OCT | N6: NOV | O6: DIC | Q6: ACUMUL. | R6: ACUMUL. | S6: VARIACION | T6: % | V6: ANUAL | X6: =+PETRAL!X6 -> 45778
B8: VENTAS | D8: 1171040.6 | E8: 955778.87 | F8: 1222513.1 | G8: 1057662.1 | H8: 915690.05 | I8: 0 | J8: 0 | K8: 0 | L8: 0 | M8: 0 | N8: 0 | O8: 0 | Q8: 5322684.6 | R8: 5247975 | S8: 74709.63 | T8: 1.4235897 | V8: 11025680 | X8: 5013071.8
A9: * HIRE | B9: HIRE | D9: 844069.75 | E9: 808897.03 | F9: 859884.72 | G9: 814061.18 | H9: 588616.35 | I9: 0 | J9: 0 | K9: 0 | L9: 0 | M9: 0 | N9: 0 | O9: 0 | Q9: 3915529 | R9: 4047975 | S9: -132445.97 | T9: -3.2719068 | V9: 8635680 | X9: 3661399.3
B10: VENTA DE TERCEROS | D10: 0 | E10: 0 | F10: 0 | G10: 0 | H10: 0 | I10: 0 | J10: 0 | K10: 0 | L10: 0 | M10: 0 | N10: 0 | O10: 0 | Q10: 0 | R10: 0 | S10: 0 | T10: 0 | V10: 0 | X10: 0
A11: * DEMORAS | B11: DEMORAS | D11: 273123.92 | E11: 85124.65 | F11: 336325.55 | G11: 188440.91 | H11: 293507.16 | I11: 0 | J11: 0 | K11: 0 | L11: 0 | M11: 0 | N11: 0 | O11: 0 | Q11: 1176522.2 | R11: 900000 | S11: 276522.19 | T11: 30.724688 | V11: 1750000 | X11: 1160979.3
A12: * INGRESOS DE PUERTO | B12: INGRESOS DE PUERTO | D12: 53846.9 | E12: 61757.19 | F12: 26302.78 | G12: 55160 | H12: 33566.54 | I12: 0 | J12: 0 | K12: 0 | L12: 0 | M12: 0 | N12: 0 | O12: 0 | Q12: 230633.41 | R12: 300000 | S12: -69366.59 | T12: -23.122197 | V12: 640000 | X12: 190693.28
A13: * OTROS INGRESOS | B13: OTROS INGRESOS | D13: 0 | E13: 0 | F13: 0 | G13: 0 | H13: 0 | I13: 0 | J13: 0 | K13: 0 | L13: 0 | M13: 0 | N13: 0 | O13: 0 | Q13: 0 | R13: 0 | S13: 0 | T13: 0 | V13: 0 | X13: 0
B15: COSTOS DIRECTOS | D15: -380007.34 | E15: -445325.4 | F15: -133696.13 | G15: -304286.12 | H15: -251189.65 | I15: 0 | J15: 0 | K15: 0 | L15: 0 | M15: 0 | N15: 0 | O15: 0 | Q15: -1514504.6 | R15: -1802144.9 | S15: 287640.21 | T15: -15.960993 | V15: -3912743.4 | X15: -1595430.4
A16: * COMBUSTIBLE | B16: COMBUSTIBLE | D16: -119578.39 | E16: -127935.08 | F16: -77787.76 | G16: -107266.88 | H16: -138748.29 | I16: 0 | J16: 0 | K16: 0 | L16: 0 | M16: 0 | N16: 0 | O16: 0 | Q16: -571316.4 | R16: -797144.85 | S16: 225828.45 | T16: -28.329663 | V16: -1768743.4 | X16: -699598.52
A17: * GASTOS DE PUERTO | B17: GASTOS DE PUERTO | D17: -260428.95 | E17: -317390.32 | F17: -52458.38 | G17: -197019.24 | H17: -111426.36 | I17: 0 | J17: 0 | K17: 0 | L17: 0 | M17: 0 | N17: 0 | O17: 0 | Q17: -938723.25 | R17: -1005000 | S17: 66276.75 | T17: -6.5947015 | V17: -2144000 | X17: -895831.83
B18: COSTOS DE DEMORA | D18: 0 | E18: 0 | F18: 0 | G18: 0 | H18: 0 | I18: 0 | J18: 0 | K18: 0 | L18: 0 | M18: 0 | N18: 0 | O18: 0 | Q18: 0 | R18: 0 | S18: 0 | T18: 0 | V18: 0 | X18: 0
B19: COMISION BROCKERAGE | D19: 0 | E19: 0 | F19: 0 | G19: 0 | H19: 0 | I19: 0 | J19: 0 | K19: 0 | L19: 0 | M19: 0 | N19: 0 | O19: 0 | Q19: 0 | R19: 0 | S19: 0 | T19: 0 | V19: 0 | X19: 0
B20: COMISIONES VARIAS | D20: 0 | E20: 0 | F20: 0 | G20: 0 | H20: 0 | I20: 0 | J20: 0 | K20: 0 | L20: 0 | M20: 0 | N20: 0 | O20: 0 | Q20: 0 | R20: 0 | S20: 0 | T20: 0 | V20: 0 | X20: 0
A21: * OTROS COSTOS DIRECTOS | B21: OTROS COSTOS DIRECTOS | D21: 0 | E21: 0 | F21: -3449.99 | G21: 0 | H21: -1015 | I21: 0 | J21: 0 | K21: 0 | L21: 0 | M21: 0 | N21: 0 | O21: 0 | Q21: -4464.99 | R21: 0 | S21: -4464.99 | T21: 0 | V21: 0 | X21: 0
B22: GASTO PUERTO POR RECIBIR | D22: 0 | E22: 0 | F22: 0 | G22: 0 | H22: 0 | I22: 0 | J22: 0 | K22: 0 | L22: 0 | M22: 0 | N22: 0 | O22: 0 | Q22: 0 | R22: 0 | S22: 0 | T22: 0 | V22: 0 | X22: 0
B24: TIME CHARTER EQUIVALENT | D24: 791033.23 | E24: 510453.47 | F24: 1088816.9 | G24: 753375.97 | H24: 664500.4 | I24: 0 | J24: 0 | K24: 0 | L24: 0 | M24: 0 | N24: 0 | O24: 0 | Q24: 3808180 | R24: 3445830.1 | S24: 362349.84 | T24: 10.515604 | V24: 7112936.6 | X24: 3417641.5
B26: COSTO DE ARRIENDO NAVES | D26: 0 | E26: 0 | F26: 0 | G26: 0 | H26: 0 | I26: 0 | J26: 0 | K26: 0 | L26: 0 | M26: 0 | N26: 0 | O26: 0 | Q26: 0 | R26: 0 | S26: 0 | T26: 0 | V26: 0 | X26: 0
B28: MARGEN BRUTO | D28: 791033.23 | E28: 510453.47 | F28: 1088816.9 | G28: 753375.97 | H28: 664500.4 | I28: 0 | J28: 0 | K28: 0 | L28: 0 | M28: 0 | N28: 0 | O28: 0 | Q28: 3808180 | R28: 3445830.1 | S28: 362349.84 | T28: 10.515604 | V28: 7112936.6 | X28: 3417641.5
B30: GTOS. PERSONAL A BORDO | D30: -167083.49 | E30: -199245.36 | F30: -168976.35 | G30: -160871.15 | H30: -164645.54 | I30: 0 | J30: 0 | K30: 0 | L30: 0 | M30: 0 | N30: 0 | O30: 0 | Q30: -860821.89 | R30: -928141.88 | S30: 67319.99 | T30: -7.2532003 | V30: -2172021.5 | X30: -780384.43
B31: GASTOS DE PERSONAL | D31: -167083.49 | E31: -199245.36 | F31: -168976.35 | G31: -160871.15 | H31: -164645.54 | I31: 0 | J31: 0 | K31: 0 | L31: 0 | M31: 0 | N31: 0 | O31: 0 | Q31: -860821.89 | R31: -928141.88 | S31: 67319.99 | T31: -7.2532003 | V31: -2172021.5 | X31: -780384.43
A33: * SUELDOS | B33: SUELDOS | D33: -106436.85 | E33: -146001.06 | F33: -94427.89 | G33: -99041.96 | H33: -94680.08 | I33: 0 | J33: 0 | K33: 0 | L33: 0 | M33: 0 | N33: 0 | O33: 0 | Q33: -540587.84 | R33: -523020.72 | S33: -17567.12 | T33: 3.3587809 | V33: -1205715.7 | X33: -474804.85
A34: * VACACIONES | B34: VACACIONES | D34: -5946.48 | E34: -5197.26 | F34: -8114.44 | G34: -3904.9 | H34: -10960.45 | I34: 0 | J34: 0 | K34: 0 | L34: 0 | M34: 0 | N34: 0 | O34: 0 | Q34: -34123.53 | R34: -40071.25 | S34: 5947.72 | T34: -14.842861 | V34: -97697.77 | X34: -22934.83
A35: * GRATIFICACIONES | B35: GRATIFICACIONES | D35: -9437.85 | E35: -10807.28 | F35: -18247.81 | G35: -12990.4 | H35: -19652.7 | I35: 0 | J35: 0 | K35: 0 | L35: 0 | M35: 0 | N35: 0 | O35: 0 | Q35: -71136.04 | R35: -106070.91 | S35: 34934.87 | T35: -32.935392 | V35: -243953.31 | X35: -62879.05
A36: * BENEFICIOS SOCIALES | B36: BENEFICIOS SOCIALES | D36: -10898.35 | E36: -7528.37 | F36: -11263.49 | G36: 3249.31 | H36: -7781.14 | I36: 0 | J36: 0 | K36: 0 | L36: 0 | M36: 0 | N36: 0 | O36: 0 | Q36: -34222.04 | R36: -45833.1 | S36: 11611.06 | T36: -25.333351 | V36: -111745.8 | X36: -32690.4
A37: * ESSALUD | B37: ESSALUD | D37: -5844.39 | E37: -8418.46 | F37: -5903.92 | G37: -5330.18 | H37: -5793.57 | I37: 0 | J37: 0 | K37: 0 | L37: 0 | M37: 0 | N37: 0 | O37: 0 | Q37: -31290.52 | R37: -35659.45 | S37: 4368.93 | T37: -12.251815 | V37: -86941.45 | X37: -30459.86
A38: * E.P.S. /GASTOS MEDICOS | B38: E.P.S. /GASTOS MEDICOS | D38: -3940.29 | E38: -4756.12 | F38: -2926.23 | G38: -379.22 | H38: -5351.98 | I38: 0 | J38: 0 | K38: 0 | L38: 0 | M38: 0 | N38: 0 | O38: 0 | Q38: -17353.84 | R38: -18000 | S38: 646.16 | T38: -3.5897778 | V38: -43200 | X38: -20776.96
A39: * VESTUARIO | B39: VESTUARIO | D39: -5435.43 | E39: -8.7 | F39: 0 | G39: -12.75 | H39: 0 | I39: 0 | J39: 0 | K39: 0 | L39: 0 | M39: 0 | N39: 0 | O39: 0 | Q39: -5456.88 | R39: -4250 | S39: -1206.88 | T39: 28.397176 | V39: -10200 | X39: -2613.63
A40: * CAPACITACION | B40: CAPACITACION | D40: -28.93 | E40: -40.14 | F40: 0 | G40: -199.01 | H40: -578.26 | I40: 0 | J40: 0 | K40: 0 | L40: 0 | M40: 0 | N40: 0 | O40: 0 | Q40: -846.34 | R40: -4000 | S40: 3153.66 | T40: -78.8415 | V40: -9600 | X40: -1473.88
A41: * TRASLADO DE TRIPULACION | B41: TRASLADO DE TRIPULACION | D41: -6980.65 | E41: -4484.72 | F41: -8437 | G41: -7381.07 | H41: -7914.73 | I41: 0 | J41: 0 | K41: 0 | L41: 0 | M41: 0 | N41: 0 | O41: 0 | Q41: -35198.17 | R41: -36000 | S41: 801.83 | T41: -2.2273056 | V41: -86400 | X41: -34927.27
A42: * OTROS GTOS. DE PERSONAL | B42: OTROS GTOS. DE PERSONAL | D42: -12153.54 | E42: -11988.96 | F42: -11700.03 | G42: -11887.56 | H42: -11981.9 | I42: 0 | J42: 0 | K42: 0 | L42: 0 | M42: 0 | N42: 0 | O42: 0 | Q42: -59711.99 | R42: -65516.8 | S42: 5804.81 | T42: -8.8600328 | V42: -157240.32 | X42: -58782.8
A43: * VIVERES DE TRIPULACION | B43: VIVERES DE TRIPULACION | D43: 19.27 | E43: -14.29 | F43: -7955.54 | G43: -22993.41 | H43: 49.27 | I43: 0 | J43: 0 | K43: 0 | L43: 0 | M43: 0 | N43: 0 | O43: 0 | Q43: -30894.7 | R43: -49719.65 | S43: 18824.95 | T43: -37.862193 | V43: -119327.16 | X43: -38040.9
B45: GASTOS DE LA NAVE | D45: -73760.1 | E45: -131615.3 | F45: -96764.81 | G45: -92506.02 | H45: -97393.13 | I45: 0 | J45: 0 | K45: 0 | L45: 0 | M45: 0 | N45: 0 | O45: 0 | Q45: -492039.36 | R45: -400670 | S45: -91369.36 | T45: 22.804143 | V45: -911892 | W45: 0 | X45: -370459.65
A46: * LUBRICANTES | B46: LUBRICANTES | D46: -18300 | E46: -28016.81 | F46: -1.31 | G46: -4531.57 | H46: -24493.32 | I46: 0 | J46: 0 | K46: 0 | L46: 0 | M46: 0 | N46: 0 | O46: 0 | Q46: -75343.01 | R46: -40940 | S46: -34403.01 | T46: 84.032755 | V46: -119820 | X46: -44169.82
A47: * REPUESTOS Y MANTENIMIEN | B47: REPUESTOS Y MANTENIMIENTO | D47: -10335.88 | E47: -75697.49 | F47: -62322.06 | G47: -36500.46 | H47: -20426.61 | I47: 0 | J47: 0 | K47: 0 | L47: 0 | M47: 0 | N47: 0 | O47: 0 | Q47: -205282.5 | R47: -189000 | S47: -16282.5 | T47: 8.6150794 | V47: -384000 | X47: -119119.57
A48: * MATERIAL CONSUMIBLE | B48: MATERIAL CONSUMIBLE | D48: -29609.8 | E48: -4375.92 | F48: -17524.22 | G48: -22403.02 | H48: -23457.11 | I48: 0 | J48: 0 | K48: 0 | L48: 0 | M48: 0 | N48: 0 | O48: 0 | Q48: -97370.07 | R48: -66000 | S48: -31370.07 | T48: 47.530409 | V48: -158400 | X48: -88566.88
A49: * CERTIF. /INSPECCION | B49: CERTIF. /INSPECCION | D49: -615.6 | E49: -3713.66 | F49: -1036.49 | G49: -10613.02 | H49: -12051.48 | I49: 0 | J49: 0 | K49: 0 | L49: 0 | M49: 0 | N49: 0 | O49: 0 | Q49: -28030.25 | R49: -20450 | S49: -7580.25 | T49: 37.067237 | V49: -47400 | X49: -22219.44
...

Sheet TABLONES GRR3
B2: US$ Dolar | C2: Enero | D2: Febrero | E2: Marzo | F2: Abril | G2: Mayo | H2: Junio | I2: Julio | J2: Agosto | K2: Setiembre | L2: Octubre | M2: Noviembre | N2: Diciembre | O2: Acum. 2026 | P2: Ppto.Acum a 3 | Q2: Variacion | R2: Ppto Anual | S2: % | T2: Ppto Mens | U2: Real A o anterior
B3: ** VENTAS | C3: -1171040.6 | D3: -955778.87 | E3: -1222513.1 | F3: 0 | G3: 0 | H3: 0 | I3: 0 | J3: 0 | K3: 0 | L3: 0 | M3: 0 | N3: 0 | O3: -3349332.5 | P3: -3148785 | Q3: 200547.49 | R3: -11025680 | S3: -6.369 | T3: -1049595 | U3: 0
B4: 704121 FLETES A TERC-NAV P | C4: 0 | D4: 0 | E4: 0 | F4: 0 | G4: 0 | H4: 0 | I4: 0 | J4: 0 | K4: 0 | L4: 0 | M4: 0 | N4: 0 | O4: 0 | P4: -2428785 | Q4: -2428785 | R4: -8635680 | S4: 100 | T4: -809595 | U4: 0
B5: 703213 FLETES A T-NAV PR L | C5: -844069.75 | D5: -808897.03 | E5: -859884.72 | F5: 0 | G5: 0 | H5: 0 | I5: 0 | J5: 0 | K5: 0 | L5: 0 | M5: 0 | N5: 0 | O5: -2512851.5 | P5: 0 | Q5: 2512851.5 | R5: 0 | S5: 0 | T5: 0 | U5: 0
B6: * HIRE | C6: -844069.75 | D6: -808897.03 | E6: -859884.72 | F6: 0 | G6: 0 | H6: 0 | I6: 0 | J6: 0 | K6: 0 | L6: 0 | M6: 0 | N6: 0 | O6: -2512851.5 | P6: -2428785 | Q6: 84066.5 | R6: -8635680 | S6: -3.4613 | T6: -809595 | U6: 0
B7: 704123 DEMORAS | C7: 0 | D7: 0 | E7: 0 | F7: 0 | G7: 0 | H7: 0 | I7: 0 | J7: 0 | K7: 0 | L7: 0 | M7: 0 | N7: 0 | O7: 0 | P7: -540000 | Q7: -540000 | R7: -1750000 | S7: 100 | T7: -180000 | U7: 0
B8: 703115 DEMORAS EXPORTACION | C8: 240599.03 | D8: 13999.95 | E8: -204215.85 | F8: 0 | G8: 0 | H8: 0 | I8: 0 | J8: 0 | K8: 0 | L8: 0 | M8: 0 | N8: 0 | O8: 50383.13 | P8: 0 | Q8: -50383.13 | R8: 0 | S8: 0 | T8: 0 | U8: 0
B9: 703215 DEMORAS -LOCAL | C9: -513722.95 | D9: -99124.6 | E9: -132109.7 | F9: 0 | G9: 0 | H9: 0 | I9: 0 | J9: 0 | K9: 0 | L9: 0 | M9: 0 | N9: 0 | O9: -744957.25 | P9: 0 | Q9: 744957.25 | R9: 0 | S9: 0 | T9: 0 | U9: 0
B10: * DEMORAS | C10: -273123.92 | D10: -85124.65 | E10: -336325.55 | F10: 0 | G10: 0 | H10: 0 | I10: 0 | J10: 0 | K10: 0 | L10: 0 | M10: 0 | N10: 0 | O10: -694574.12 | P10: -540000 | Q10: 154574.12 | R10: -1750000 | S10: -28.6248 | T10: -180000 | U10: 0
B11: 704136 SERV DE ATENC EN PU | C11: 0 | D11: 0 | E11: 0 | F11: 0 | G11: 0 | H11: 0 | I11: 0 | J11: 0 | K11: 0 | L11: 0 | M11: 0 | N11: 0 | O11: 0 | P11: -180000 | Q11: -180000 | R11: -640000 | S11: 100 | T11: -60000 | U11: 0
B12: 703118 SERV ATENC EN PUE E | C12: 20000 | D12: -6000 | E12: 26000 | F12: 0 | G12: 0 | H12: 0 | I12: 0 | J12: 0 | K12: 0 | L12: 0 | M12: 0 | N12: 0 | O12: 40000 | P12: 0 | Q12: -40000 | R12: 0 | S12: 0 | T12: 0 | U12: 0
B13: 703218 SERV ATENC EN PUE L | C13: -73846.9 | D13: -55757.19 | E13: -52302.78 | F13: 0 | G13: 0 | H13: 0 | I13: 0 | J13: 0 | K13: 0 | L13: 0 | M13: 0 | N13: 0 | O13: -181906.87 | P13: 0 | Q13: 181906.87 | R13: 0 | S13: 0 | T13: 0 | U13: 0
B14: * INGRESOS DE PUERTO | C14: -53846.9 | D14: -61757.19 | E14: -26302.78 | F14: 0 | G14: 0 | H14: 0 | I14: 0 | J14: 0 | K14: 0 | L14: 0 | M14: 0 | N14: 0 | O14: -141906.87 | P14: -180000 | Q14: -38093.13 | R14: -640000 | S14: 21.1628 | T14: -60000 | U14: 0
... B125: ******* EBITDA | C125: -537590.65 | D125: -168454.17 | E125: -810803.72 | F125: 0 | G125: 0 | H125: 0 | I125: 0 | J125: 0 | K125: 0 | L125: 0 | M125: 0 | N125: 0 | O125: -1516848.5 | P125: -1247890.5 | Q125: 268958.02 | R125: -3890929 | S125: -21.553 | T125: -412047.57 | U125: 0

Sheet Hoja3
B2: US$ Dolar | C2: Enero | D2: Febrero | E2: Marzo | F2: Abril | G2: Mayo | H2: Junio | I2: Julio | J2: Agosto | K2: Setiembre | L2: Octubre | M2: Noviembre | N2: Diciembre | O2: Acum. 2025 | P2: Ppto.Acum a 11 | Q2: Variacion | R2: Ppto Anual | S2: % | T2: Ppto Mens | U2: Real A o anterior
B3: ** VENTAS | C3: 0 | D3: 0 | E3: 0 | F3: 0 | G3: 0 | H3: 0 | I3: 0 | J3: 0 | K3: 0 | L3: -9188732 | M3: -685632.22 | N3: 0 | O3: -9874364.2 | P3: -9531536.3 | Q3: 342827.83 | R3: -10570994 | S3: -3.5968 | T3: -994882.85 | U3: 0
B4: 704121 FLETES A TERC-NAV P | C4: 0 | D4: 0 | E4: 0 | F4: 0 | G4: 0 | H4: 0 | I4: 0 | J4: 0 | K4: 0 | L4: 0 | M4: 0 | N4: 0 | O4: 0 | P4: -7659375 | Q4: -7659375 | R4: -8535000 | S4: 100 | T4: -814050 | U4: 0
B5: 703213 FLETES A T-NAV PR L | C5: 0 | D5: 0 | E5: 0 | F5: 0 | G5: 0 | H5: 0 | I5: 0 | J5: 0 | K5: 0 | L5: -6495536.3 | M5: -306386.56 | N5: 0 | O5: -6801922.8 | P5: 0 | Q5: 6801922.8 | R5: 0 | S5: 0 | T5: 0 | U5: 0
B6: * HIRE | C6: 0 | D6: 0 | E6: 0 | F6: 0 | G6: 0 | H6: 0 | I6: 0 | J6: 0 | K6: 0 | L6: -6495536.3 | M6: -306386.56 | N6: 0 | O6: -6801922.8 | P6: -7659375 | Q6: -857452.15 | R6: -8535000 | S6: 11.1948 | T6: -814050 | U6: 0
B7: 704123 DEMORAS | C7: 0 | D7: 0 | E7: 0 | F7: 0 | G7: 0 | H7: 0 | I7: 0 | J7: 0 | K7: 0 | L7: 0 | M7: 0 | N7: 0 | O7: 0 | P7: -1329161.4 | Q7: -1329161.4 | R7: -1449994.2 | S7: 100 | T7: -120832.85 | U7: 0
B8: 703115 DEMORAS EXPORTACION | C8: 0 | D8: 0 | E8: 0 | F8: 0 | G8: 0 | H8: 0 | I8: 0 | J8: 0 | K8: 0 | L8: -121922.94 | M8: 110941.22 | N8: 0 | O8: -10981.72 | P8: 0 | Q8: 10981.72 | R8: 0 | S8: 0 | T8: 0 | U8: 0
B9: 703215 DEMORAS -LOCAL | C9: 0 | D9: 0 | E9: 0 | F9: 0 | G9: 0 | H9: 0 | I9: 0 | J9: 0 | K9: 0 | L9: -2232862.1 | M9: -451389.86 | N9: 0 | O9: -2684252 | P9: 0 | Q9: 2684252 | R9: 0 | S9: 0 | T9: 0 | U9: 0
B10: * DEMORAS | C10: 0 | D10: 0 | E10: 0 | F10: 0 | G10: 0 | H10: 0 | I10: 0 | J10: 0 | K10: 0 | L10: -2354785 | M10: -340448.64 | N10: 0 | O10: -2695233.7 | P10: -1329161.4 | Q10: 1366072.3 | R10: -1449994.2 | S10: -102.777 | T10: -120832.85 | U10: 0
B11: 704136 SERV DE ATENC EN PU | C11: 0 | D11: 0 | E11: 0 | F11: 0 | G11: 0 | H11: 0 | I11: 0 | J11: 0 | K11: 0 | L11: 0 | M11: 0 | N11: 0 | O11: 0 | P11: -543000 | Q11: -543000 | R11: -586000 | S11: 100 | T11: -60000 | U11: 0
B12: 703118 SERV ATENC EN PUE E | C12: 0 | D12: 0 | E12: 0 | F12: 0 | G12: 0 | H12: 0 | I12: 0 | J12: 0 | K12: 0 | L12: 7510 | M12: -9904 | N12: 0 | O12: -2394 | P12: 0 | Q12: 2394 | R12: 0 | S12: 0 | T12: 0 | U12: 0
B13: 703218 SERV ATENC EN PUE L | C13: 0 | D13: 0 | E13: 0 | F13: 0 | G13: 0 | H13: 0 | I13: 0 | J13: 0 | K13: 0 | L13: -345920.63 | M13: -28893.02 | N13: 0 | O13: -374813.65 | P13: 0 | Q13: 374813.65 | R13: 0 | S13: 0 | T13: 0 | U13: 0
B14: * INGRESOS DE PUERTO | C14: 0 | D14: 0 | E14: 0 | F14: 0 | G14: 0 | H14: 0 | I14: 0 | J14: 0 | K14: 0 | L14: -338410.63 | M14: -38797.02 | N14: 0 | O14: -377207.65 | P14: -543000 | Q14: -165792.35 | R14: -586000 | S14: 30.5327 | T14: -60000 | U14: 0
... B134: ******* EBITDA | C134: 0 | D134: 0 | E134: 0 | F134: 0 | G134: 0 | H134: 0 | I134: 0 | J134: 0 | K134: 0 | L134: -3894595.4 | M134: -225060.95 | N134: 0 | O134: -4119656.3 | P134: -3753646.6 | Q134: 366009.72 | R134: -4214174.1 | S134: -9.7508 | T134: -456319.51 | U134: 0

Sheet Flota Contratada
Z1: =+PETRAL!Z1 -> 5
B2: Control Presupuestal
B3: =+PETRAL!B3 -> 46143 | D3: FLOTA CONTRATADA
Q5: REAL | R5: PRESUP. | V5: PPTO. | X5: Real Acum.
B6: (US$ Dólares) | D6: ENE | E6: FEB | F6: MAR | G6: ABR | H6: MAY | I6: JUN | J6: JUL | K6: AGO | L6: SET | M6: OCT | N6: NOV | O6: DIC | Q6: ACUMUL. | R6: ACUMUL. | S6: VARIACION | T6: % | V6: ANUAL | X6: =+PETRAL!X6 -> 45778
B8: VENTAS | D8: 0 | E8: 0 | F8: 0 | G8: 0 | H8: 472589.52 | I8: 0 | J8: 0 | K8: 0 | L8: 0 | M8: 0 | N8: 0 | O8: 0 | Q8: 472589.52 | R8: 0 | S8: 472589.52 | T8: 0 | V8: 0 | X8: 0
A9: * HIRE | B9: HIRE | D9: 0 | E9: 0 | F9: 0 | G9: 0 | H9: 362131.63 | I9: 0 | J9: 0 | K9: 0 | L9: 0 | M9: 0 | N9: 0 | O9: 0 | Q9: 362131.63 | R9: 0 | S9: 362131.63 | T9: 0 | V9: 0 | X9: 0
B10: VENTA DE TERCEROS | D10: 0 | E10: 0 | F10: 0 | G10: 0 | H10: 0 | I10: 0 | J10: 0 | K10: 0 | L10: 0 | M10: 0 | N10: 0 | O10: 0 | Q10: 0 | R10: 0 | S10: 0 | T10: 0 | V10: 0 | X10: 0
A11: * DEMORAS | B11: DEMORAS | D11: 0 | E11: 0 | F11: 0 | G11: 0 | H11: 110457.89 | I11: 0 | J11: 0 | K11: 0 | L11: 0 | M11: 0 | N11: 0 | O11: 0 | Q11: 110457.89 | R11: 0 | S11: 110457.89 | T11: 0 | V11: 0 | X11: 0
A12: * INGRESOS DE PUERTO | B12: INGRESOS DE PUERTO | D12: 0 | E12: 0 | F12: 0 | G12: 0 | H12: 0 | I12: 0 | J12: 0 | K12: 0 | L12: 0 | M12: 0 | N12: 0 | O12: 0 | Q12: 0 | R12: 0 | S12: 0 | T12: 0 | V12: 0 | X12: 0
A13: * OTROS INGRESOS | B13: OTROS INGRESOS | D13: 0 | E13: 0 | F13: 0 | G13: 0 | H13: 0 | I13: 0 | J13: 0 | K13: 0 | L13: 0 | M13: 0 | N13: 0 | O13: 0 | Q13: 0 | R13: 0 | S13: 0 | T13: 0 | V13: 0 | X13: 0
B15: COSTOS DIRECTOS | D15: 0 | E15: 0 | F15: 0 | G15: 0 | H15: -112500 | I15: 0 | J15: 0 | K15: 0 | L15: 0 | M15: 0 | N15: 0 | O15: 0 | Q15: -112500 | R15: 0 | S15: -112500 | T15: 0 | V15: 0 | X15: 16617.69
A16: * COMBUSTIBLE | B16: COMBUSTIBLE | D16: 0 | E16: 0 | F16: 0 | G16: 0 | H16: 0 | I16: 0 | J16: 0 | K16: 0 | L16: 0 | M16: 0 | N16: 0 | O16: 0 | Q16: 0 | R16: 0 | S16: 0 | T16: 0 | V16: 0 | X16: 0
A17: * GASTOS DE PUERTO | B17: GASTOS DE PUERTO | D17: 0 | E17: 0 | F17: 0 | G17: 0 | H17: 0 | I17: 0 | J17: 0 | K17: 0 | L17: 0 | M17: 0 | N17: 0 | O17: 0 | Q17: 0 | R17: 0 | S17: 0 | T17: 0 | V17: 0 | X17: 16617.69
A18: * COSTOS DEMORAS | B18: COSTOS DE DEMORA | D18: 0 | E18: 0 | F18: 0 | G18: 0 | H18: -112500 | I18: 0 | J18: 0 | K18: 0 | L18: 0 | M18: 0 | N18: 0 | O18: 0 | Q18: -112500 | R18: 0 | S18: -112500 | T18: 0 | V18: 0 | X18: 0
B19: COMISIONES VARIAS | D19: 0 | E19: 0 | F19: 0 | G19: 0 | H19: 0 | I19: 0 | J19: 0 | K19: 0 | L19: 0 | M19: 0 | N19: 0 | O19: 0 | Q19: 0 | R19: 0 | S19: 0 | T19: 0 | V19: 0 | X19: 0
B20: OTROS COSTOS DIRECTOS | D20: 0 | E20: 0 | F20: 0 | G20: 0 | H20: 0 | I20: 0 | J20: 0 | K20: 0 | L20: 0 | M20: 0 | N20: 0 | O20: 0 | Q20: 0 | R20: 0 | S20: 0 | T20: 0 | V20: 0 | X20: 0
B24: TIME CHARTER EQUIVALENT | D24: 0 | E24: 0 | F24: 0 | G24: 0 | H24: 360089.52 | I24: 0 | J24: 0 | K24: 0 | L24: 0 | M24: 0 | N24: 0 | O24: 0 | Q24: 360089.52 | R24: 0 | S24: 360089.52 | T24: 0 | V24: 0 | X24: 16617.69
A26: * COSTOS DE HIRE | B26: COSTO DE ARRIENDO NAVES | D26: 0 | E26: 0 | F26: 0 | G26: 0 | H26: -417912.29 | I26: 0 | J26: 0 | K26: 0 | L26: 0 | M26: 0 | N26: 0 | O26: 0 | Q26: -417912.29 | R26: 0 | S26: -417912.29 | T26: 0 | V26: 0 | X26: 0
B28: MARGEN BRUTO | D28: 0 | E28: 0 | F28: 0 | G28: 0 | H28: -57822.77 | I28: 0 | J28: 0 | K28: 0 | L28: 0 | M28: 0 | N28: 0 | O28: 0 | Q28: -57822.77 | R28: 0 | S28: -57822.77 | T28: 0 | V28: 0 | X28: 16617.69
B30: GTOS. PERSONAL A BORDO | D30: 0 | E30: 0 | F30: 0 | G30: 0 | H30: 0 | I30: 0 | J30: 0 | K30: 0 | L30: 0 | M30: 0 | N30: 0 | O30: 0 | Q30: 0 | R30: 0 | S30: 0 | T30: 0 | V30: 0 | X30: 0
B31: GASTOS DE PERSONAL | D31: 0 | E31: 0 | F31: 0 | G31: 0 | H31: 0 | I31: 0 | J31: 0 | K31: 0 | L31: 0 | M31: 0 | N31: 0 | O31: 0 | Q31: 0 | R31: 0 | S31: 0 | T31: 0 | V31: 0 | X31: 0
B33: SUELDOS | D33: 0 | E33: 0 | F33: 0 | G33: 0 | H33: 0 | I33: 0 | J33: 0 | K33: 0 | L33: 0 | M33: 0 | N33: 0 | O33: 0 | Q33: 0 | R33: 0 | S33: 0 | T33: 0 | V33: 0 | X33: 0
B34: VACACIONES | D34: 0 | E34: 0 | F34: 0 | G34: 0 | H34: 0 | I34: 0 | J34: 0 | K34: 0 | L34: 0 | M34: 0 | N34: 0 | O34: 0 | Q34: 0 | R34: 0 | S34: 0 | T34: 0 | V34: 0 | X34: 0
B35: GRATIFICACIONES | D35: 0 | E35: 0 | F35: 0 | G35: 0 | H35: 0 | I35: 0 | J35: 0 | K35: 0 | L35: 0 | M35: 0 | N35: 0 | O35: 0 | Q35: 0 | R35: 0 | S35: 0 | T35: 0 | V35: 0 | X35: 0
B36: BENEFICIOS SOCIALES | D36: 0 | E36: 0 | F36: 0 | G36: 0 | H36: 0 | I36: 0 | J36: 0 | K36: 0 | L36: 0 | M36: 0 | N36: 0 | O36: 0 | Q36: 0 | R36: 0 | S36: 0 | T36: 0 | V36: 0 | X36: 0
B37: ESSALUD | D37: 0 | E37: 0 | F37: 0 | G37: 0 | H37: 0 | I37: 0 | J37: 0 | K37: 0 | L37: 0 | M37: 0 | N37: 0 | O37: 0 | Q37: 0 | R37: 0 | S37: 0 | T37: 0 | V37: 0 | X37: 0
B38: E.P.S. /GASTOS MEDICOS | D38: 0 | E38: 0 | F38: 0 | G38: 0 | H38: 0 | I38: 0 | J38: 0 | K38: 0 | L38: 0 | M38: 0 | N38: 0 | O38: 0 | Q38: 0 | R38: 0 | S38: 0 | T38: 0 | V38: 0 | X38: 0
B39: VESTUARIO | D39: 0 | E39: 0 | F39: 0 | G39: 0 | H39: 0 | I39: 0 | J39: 0 | K39: 0 | L39: 0 | M39: 0 | N39: 0 | O39: 0 | Q39: 0 | R39: 0 | S39: 0 | T39: 0 | V39: 0 | X39: 0
B40: CAPACITACION | D40: 0 | E40: 0 | F40: 0 | G40: 0 | H40: 0 | I40: 0 | J40: 0 | K40: 0 | L40: 0 | M40: 0 | N40: 0 | O40: 0 | Q40: 0 | R40: 0 | S40: 0 | T40: 0 | V40: 0 | X40: 0
B41: TRASLADO DE TRIPULACION | D41: 0 | E41: 0 | F41: 0 | G41: 0 | H41: 0 | I41: 0 | J41: 0 | K41: 0 | L41: 0 | M41: 0 | N41: 0 | O41: 0 | Q41: 0 | R41: 0 | S41: 0 | T41: 0 | V41: 0 | X41: 0
... B60: CASCO Y MAQUINA | D60: 0 | E60: 0 | F60: 0 | G60: 0 | H60: 0 | I60: 0 | J60: 0 | K60: 0 | L60: 0 | M60: 0 | N60: 0 | O60: 0 | Q60: 0 | R60: 0 | S60: 0 | T60: 0 | V60: 0 | X60: 0
A61: * PANDI | B61: PANDI | D61: 0 | E61: 0 | F61: 0 | G61: 0 | H61: 0 | I61: 0 | J61: 0 | K61: 0 | L61: 0 | M61: 0 | N61: 0 | O61: 0 | Q61: 0 | R61: 0 | S61: 0 | T61: 0 | V61: 0 | X61: 0
B62: DEDUCIBLES Y OTROS | D62: 0 | E62: 0 | F62: 0 | G62: 0 | H62: 0 | I62: 0 | J62: 0 | K62: 0 | L62: 0 | M62: 0 | N62: 0 | O62: 0 | Q62: 0 | R62: 0 | S62: 0 | T62: 0 | V62: 0 | X62: 0
X63: 0
B64: OPERATING COST | D64: 0 | E64: 0 | F64: 0 | G64: 0 | H64: 0 | I64: 0 | J64: 0 | K64: 0 | L64: 0 | M64: 0 | N64: 0 | O64: 0 | Q64: 0 | R64: 0 | S64: 0 | T64: 0 | V64: 0 | X64: 0
B66: BARE BOAT EQUIVALENT | D66: 0 | E66: 0 | F66: 0 | G66: 0 | H66: 360089.52 | I66: 0 | J66: 0 | K66: 0 | L66: 0 | M66: 0 | N66: 0 | O66: 0 | Q66: 360089.52 | R66: 0 | S66: 360089.52 | T66: 0 | V66: 0 | X66: 16617.69
B68: DEPRECIACION NAVES | D68: 0 | E68: 0 | F68: 0 | G68: 0 | H68: 0 | I68: 0 | J68: 0 | K68: 0 | L68: 0 | M68: 0 | N68: 0 | O68: 0 | Q68: 0 | R68: 0 | S68: 0 | T68: 0 | V68: 0 | X68: 0
B69: COSTO IGV | D69: 0 | E69: 0 | F69: 0 | G69: 0 | H69: 0 | I69: 0 | J69: 0 | K69: 0 | L69: 0 | M69: 0 | N69: 0 | O69: 0 | Q69: 0 | R69: 0 | S69: 0 | T69: 0 | V69: 0 | X69: 0
A73: * GTOS. ADMINIST. NAVE | B73: GTOS. ADMINISTRAT. NAVE | D73: 0 | E73: 0 | F73: 0 | G73: 0 | H73: 0 | I73: 0 | J73: 0 | K73: 0 | L73: 0 | M73: 0 | N73: 0 | O73: 0 | Q73: 0 | R73: 0 | S73: 0 | T73: 0 | V73: 0 | X73: 0
...

Sheet FLOTA CONTRATADA GRR3
B2: US$ Dólar | C2: Enero | D2: Febrero | E2: Marzo | F2: Abril | G2: Mayo | H2: Junio | I2: Julio | J2: Agosto | K2: Setiembre | L2: Octubre | M2: Noviembre | N2: Diciembre | O2: Acum. 2025 | P2: Ppto.Acum a 10 | Q2: Variación | R2: Ppto Anual | S2: % | T2: Ppto Mensual | U2: Real Año anterior
B3: ** VENTAS | C3: 0 | D3: 0 | E3: 0 | F3: 0 | G3: 0 | H3: 0 | I3: 0 | J3: 0 | K3: 0 | L3: 0 | M3: =+_xlfn.XLOOKUP($B3,Hoja4!$B:$B,Hoja4!M:M,0) -> 0 | N3: =+_xlfn.XLOOKUP($B3,Hoja4!$B:$B,Hoja4!N:N,0) -> 0 | O3: =+_xlfn.XLOOKUP($B3,Hoja4!$B:$B,Hoja4!O:O,0) -> 0 | P3: =+_xlfn.XLOOKUP($B3,Hoja4!$B:$B,Hoja4!P:P,0) -> 0 | Q3: =+_xlfn.XLOOKUP($B3,Hoja4!$B:$B,Hoja4!Q:Q,0) -> 0 | R3: =+_xlfn.XLOOKUP($B3,Hoja4!$B:$B,Hoja4!R:R,0) -> 0 | S3: =+_xlfn.XLOOKUP($B3,Hoja4!$B:$B,Hoja4!S:S,0) -> 0 | T3: =+_xlfn.XLOOKUP($B3,Hoja4!$B:$B,Hoja4!T:T,0) -> 0 | U3: -4275156.7
B4: 703114 FLETES A T-NAV CO E | C4: 0 | D4: 0 | E4: 0 | F4: 0 | G4: 0 | H4: 0 | I4: 0 | J4: 0 | K4: 0 | L4: 0 | M4: =+_xlfn.XLOOKUP($B4,Hoja4!$B:$B,Hoja4!M:M,0) -> 0 | N4: =+_xlfn.XLOOKUP($B4,Hoja4!$B:$B,Hoja4!N:N,0) -> 0 | O4: =+_xlfn.XLOOKUP($B4,Hoja4!$B:$B,Hoja4!O:O,0) -> 0 | P4: =+_xlfn.XLOOKUP($B4,Hoja4!$B:$B,Hoja4!P:P,0) -> 0 | Q4: =+_xlfn.XLOOKUP($B4,Hoja4!$B:$B,Hoja4!Q:Q,0) -> 0 | R4: =+_xlfn.XLOOKUP($B4,Hoja4!$B:$B,Hoja4!R:R,0) -> 0 | S4: =+_xlfn.XLOOKUP($B4,Hoja4!$B:$B,Hoja4!S:S,0) -> 0 | T4: =+_xlfn.XLOOKUP($B4,Hoja4!$B:$B,Hoja4!T:T,0) -> 0 | U4: -2311707.6
B5: 703214 FLETES A T-NAV CO L | C5: 0 | D5: 0 | E5: 0 | F5: 0 | G5: 0 | H5: 0 | I5: 0 | J5: 0 | K5: 0 | L5: 0 | M5: =+_xlfn.XLOOKUP($B5,Hoja4!$B:$B,Hoja4!M:M,0) -> 0 | N5: =+_xlfn.XLOOKUP($B5,Hoja4!$B:$B,Hoja4!N:N,0) -> 0 | O5: =+_xlfn.XLOOKUP($B5,Hoja4!$B:$B,Hoja4!O:O,0) -> 0 | P5: =+_xlfn.XLOOKUP($B5,Hoja4!$B:$B,Hoja4!P:P,0) -> 0 | Q5: =+_xlfn.XLOOKUP($B5,Hoja4!$B:$B,Hoja4!Q:Q,0) -> 0 | R5: =+_xlfn.XLOOKUP($B5,Hoja4!$B:$B,Hoja4!R:R,0) -> 0 | S5: =+_xlfn.XLOOKUP($B5,Hoja4!$B:$B,Hoja4!S:S,0) -> 0 | T5: =+_xlfn.XLOOKUP($B5,Hoja4!$B:$B,Hoja4!T:T,0) -> 0 | U5: 0
B6: * VENTAS TERCEROS | C6: 0 | D6: 0 | E6: 0 | F6: 0 | G6: 0 | H6: 0 | I6: 0 | J6: 0 | K6: 0 | L6: 0 | M6: =+_xlfn.XLOOKUP($B6,Hoja4!$B:$B,Hoja4!M:M,0) -> 0 | N6: =+_xlfn.XLOOKUP($B6,Hoja4!$B:$B,Hoja4!N:N,0) -> 0 | O6: =+_xlfn.XLOOKUP($B6,Hoja4!$B:$B,Hoja4!O:O,0) -> 0 | P6: =+_xlfn.XLOOKUP($B6,Hoja4!$B:$B,Hoja4!P:P,0) -> 0 | Q6: =+_xlfn.XLOOKUP($B6,Hoja4!$B:$B,Hoja4!Q:Q,0) -> 0 | R6: =+_xlfn.XLOOKUP($B6,Hoja4!$B:$B,Hoja4!R:R,0) -> 0 | S6: =+_xlfn.XLOOKUP($B6,Hoja4!$B:$B,Hoja4!S:S,0) -> 0 | T6: =+_xlfn.XLOOKUP($B6,Hoja4!$B:$B,Hoja4!T:T,0) -> 0 | U6: -2311707.6
B7: 703115 DEMORAS EXPORTACION | C7: 0 | D7: 0 | E7: 0 | F7: 0 | G7: 0 | H7: 0 | I7: 0 | J7: 0 | K7: 0 | L7: 0 | M7: =+_xlfn.XLOOKUP($B7,Hoja4!$B:$B,Hoja4!M:M,0) -> 0 | N7: =+_xlfn.XLOOKUP($B7,Hoja4!$B:$B,Hoja4!N:N,0) -> 0 | O7: =+_xlfn.XLOOKUP($B7,Hoja4!$B:$B,Hoja4!O:O,0) -> 0 | P7: =+_xlfn.XLOOKUP($B7,Hoja4!$B:$B,Hoja4!P:P,0) -> 0 | Q7: =+_xlfn.XLOOKUP($B7,Hoja4!$B:$B,Hoja4!Q:Q,0) -> 0 | R7: =+_xlfn.XLOOKUP($B7,Hoja4!$B:$B,Hoja4!R:R,0) -> 0 | S7: =+_xlfn.XLOOKUP($B7,Hoja4!$B:$B,Hoja4!S:S,0) -> 0 | T7: =+_xlfn.XLOOKUP($B7,Hoja4!$B:$B,Hoja4!T:T,0) -> 0 | U7: 113655
B8: 703215 DEMORAS -LOCAL | C8: 0 | D8: 0 | E8: 0 | F8: 0 | G8: 0 | H8: 0 | I8: 0 | J8: 0 | K8: 0 | L8: 0 | M8: =+_xlfn.XLOOKUP($B8,Hoja4!$B:$B,Hoja4!M:M,0) -> 0 | N8: =+_xlfn.XLOOKUP($B8,Hoja4!$B:$B,Hoja4!N:N,0) -> 0 | O8: =+_xlfn.XLOOKUP($B8,Hoja4!$B:$B,Hoja4!O:O,0) -> 0 | P8: =+_xlfn.XLOOKUP($B8,Hoja4!$B:$B,Hoja4!P:P,0) -> 0 | Q8: =+_xlfn.XLOOKUP($B8,Hoja4!$B:$B,Hoja4!Q:Q,0) -> 0 | R8: =+_xlfn.XLOOKUP($B8,Hoja4!$B:$B,Hoja4!R:R,0) -> 0 | S8: =+_xlfn.XLOOKUP($B8,Hoja4!$B:$B,Hoja4!S:S,0) -> 0 | T8: =+_xlfn.XLOOKUP($B8,Hoja4!$B:$B,Hoja4!T:T,0) -> 0 | U8: -1755765
